Workbook

Sheet Rebalance
B1: IBX | C1: CDI | D1: Retorno | E1: CDI | G1: IBX | H1: CDI | I1: Inicial | J1: 100000 | L1: Patrimonio | M1: P&L | N1: P&L CDI | O1: Qtd Ações | P1: Qtd CDI | S1: %Ações | T1: %CDI | V1: Benchmark | W1: Estrategia | X1: BenckMark | Y1: IBX | Z1: CDI | AF1: Rebalance | AG1: Anual
A2: 40177 | B2: 21672.84 | C2: 22.35004 | G2: =VLOOKUP(A2,Aux!B:C,2,FALSE) -> 0.5 | H2: =IF(ISNUMBER(G2),1-G2,"") -> 0.5 | L2: =J1 -> 100000 | O2: =J1*G2/B2 -> 2.307035 | P2: =J1*H2/C2 -> 2237.1325 | S2: =O2*B2/L2 -> 0.5 | T2: =P2*C2/L2 -> 0.5 | V2: =L2 -> 100000 | AF2: Estrategia | AG2: BenchMark | AH2: IBX | AI2: CDI
A3: 40182 | B3: 22154.41 | C3: 22.3646 | D3: =B3/B2-1 -> 0.022219977 | E3: =C3/C2-1 -> 0.00065145297 | G3: =IF(VLOOKUP(A3,Aux!B:C,2,FALSE)=0,"",VLOOKUP(A3,Aux!B:C,2,FALSE)) | H3: =IF(ISNUMBER(G3),1-G3,"") | L3: =L2+M3+N3 -> 101143.57 | M3: =O2*(B3-B2) -> 1110.9988 | N3: =P2*(C3-C2) -> 32.572649 | O3: =IF(ISNUMBER(G3),L3*G3/B3,O2) -> 2.307035 | P3: =IF(ISNUMBER(H3),L3*H3/C3,P2) -> 2237.1325 | S3: =O3*B3/L3 -> 0.50533117 | T3: =P3*C3/L3 -> 0.49466883 | V3: =$O$2*B3+$P$2*C3 -> 101143.57 | W3: =LN(L3/L2) -> 0.011370821 | X3: =LN(V3/V2) -> 0.011370821 | Y3: =LN(B3/B2) -> 0.02197671 | Z3: =LN(C3/C2) -> 0.00065124087 | AC3: =DATE(AE3,1,1) -> 40179 | AD3: =DATE(AE3+1,1,1)-1 -> 40543 | AE3: 2010 | AF3: =EXP(SUMIFS(W:W,$A:$A,">=" &$AC3,$A:$A,"<=" &$AD3))-1 -> 0.061745224 | AG3: =EXP(SUMIFS(X:X,$A:$A,">=" &$AC3,$A:$A,"<=" &$AD3))-1 -> 0.061745224 | AH3: =EXP(SUMIFS(Y:Y,$A:$A,">=" &$AC3,$A:$A,"<=" &$AD3))-1 -> 0.02614655 | AI3: =EXP(SUMIFS(Z:Z,$A:$A,">=" &$AC3,$A:$A,"<=" &$AD3))-1 -> 0.097343897
A4: 40183 | B4: 22204.59 | C4: 22.37193 | D4: =B4/B3-1 -> 0.0022650118 | E4: =C4/C3-1 -> 0.00032775011 | G4: =IF(VLOOKUP(A4,Aux!B:C,2,FALSE)=0,"",VLOOKUP(A4,Aux!B:C,2,FALSE)) | H4: =IF(ISNUMBER(G4),1-G4,"") | L4: =L3+M4+N4 -> 101275.74 | M4: =O3*(B4-B3) -> 115.76702 | N4: =P3*(C4-C3) -> 16.398181 | O4: =IF(ISNUMBER(G4),L4*G4/B4,O3) -> 2.307035 | P4: =IF(ISNUMBER(H4),L4*H4/C4,P3) -> 2237.1325 | S4: =O4*B4/L4 -> 0.50581479 | T4: =P4*C4/L4 -> 0.49418521 | V4: =$O$2*B4+$P$2*C4 -> 101275.74 | W4: =LN(L4/L3) -> 0.0013058558 | X4: =LN(V4/V3) -> 0.0013058558 | Y4: =LN(B4/B3) -> 0.0022624505 | Z4: =LN(C4/C3) -> 0.00032769641 | AC4: =DATE(AE4,1,1) -> 40544 | AD4: =DATE(AE4+1,1,1)-1 -> 40908 | AE4: 2011 | AF4: =EXP(SUMIFS(W:W,$A:$A,">=" &$AC4,$A:$A,"<=" &$AD4))-1 -> 0.0010102348 | AG4: =EXP(SUMIFS(X:X,$A:$A,">=" &$AC4,$A:$A,"<=" &$AD4))-1 -> 0.0048634641 | AH4: =EXP(SUMIFS(Y:Y,$A:$A,">=" &$AC4,$A:$A,"<=" &$AD4))-1 -> -0.11391393 | AI4: =EXP(SUMIFS(Z:Z,$A:$A,">=" &$AC4,$A:$A,"<=" &$AD4))-1 -> 0.1159344
A5: 40184 | B5: 22351.13 | C5: 22.37926 | D5: =B5/B4-1 -> 0.0065995364 | E5: =C5/C4-1 -> 0.00032764272 | G5: =IF(VLOOKUP(A5,Aux!B:C,2,FALSE)=0,"",VLOOKUP(A5,Aux!B:C,2,FALSE)) | H5: =IF(ISNUMBER(G5),1-G5,"") | L5: =L4+M5+N5 -> 101630.21 | M5: =O4*(B5-B4) -> 338.07291 | N5: =P4*(C5-C4) -> 16.398181 | O5: =IF(ISNUMBER(G5),L5*G5/B5,O4) -> 2.307035 | P5: =IF(ISNUMBER(H5),L5*H5/C5,P4) -> 2237.1325 | S5: =O5*B5/L5 -> 0.50737709 | T5: =P5*C5/L5 -> 0.49262291 | V5: =$O$2*B5+$P$2*C5 -> 101630.21 | W5: =LN(L5/L4) -> 0.0034939484 | X5: =LN(V5/V4) -> 0.0034939484 | Y5: =LN(B5/B4) -> 0.0065778548 | Z5: =LN(C5/C4) -> 0.00032758906 | AC5: =DATE(AE5,1,1) -> 40909 | AD5: =DATE(AE5+1,1,1)-1 -> 41274 | AE5: 2012 | AF5: =EXP(SUMIFS(W:W,$A:$A,">=" &$AC5,$A:$A,"<=" &$AD5))-1 -> 0.099898388 | AG5: =EXP(SUMIFS(X:X,$A:$A,">=" &$AC5,$A:$A,"<=" &$AD5))-1 -> 0.097591824 | AH5: =EXP(SUMIFS(Y:Y,$A:$A,">=" &$AC5,$A:$A,"<=" &$AD5))-1 -> 0.11550777 | AI5: =EXP(SUMIFS(Z:Z,$A:$A,">=" &$AC5,$A:$A,"<=" &$AD5))-1 -> 0.084289005
A6: 40185 | B6: 22276.16 | C6: 22.3866 | D6: =B6/B5-1 -> -0.0033541928 | E6: =C6/C5-1 -> 0.00032798225 | G6: =IF(VLOOKUP(A6,Aux!B:C,2,FALSE)=0,"",VLOOKUP(A6,Aux!B:C,2,FALSE)) | H6: =IF(ISNUMBER(G6),1-G6,"") | L6: =L5+M6+N6 -> 101473.67 | M6: =O5*(B6-B5) -> -172.95841 | N6: =P5*(C6-C5) -> 16.420552 | O6: =IF(ISNUMBER(G6),L6*G6/B6,O5) -> 2.307035 | P6: =IF(ISNUMBER(H6),L6*H6/C6,P5) -> 2237.1325 | S6: =O6*B6/L6 -> 0.50645532 | T6: =P6*C6/L6 -> 0.49354468 | V6: =$O$2*B6+$P$2*C6 -> 101473.67 | W6: =LN(L6/L5) -> -0.0015414565 | X6: =LN(V6/V5) -> -0.0015414565 | Y6: =LN(B6/B5) -> -0.0033598307 | Z6: =LN(C6/C5) -> 0.00032792847 | AC6: =DATE(AE6,1,1) -> 41275 | AD6: =DATE(AE6+1,1,1)-1 -> 41639 | AE6: 2013 | AF6: =EXP(SUMIFS(W:W,$A:$A,">=" &$AC6,$A:$A,"<=" &$AD6))-1 -> 0.024562311 | AG6: =EXP(SUMIFS(X:X,$A:$A,">=" &$AC6,$A:$A,"<=" &$AD6))-1 -> 0.032039153 | AH6: =EXP(SUMIFS(Y:Y,$A:$A,">=" &$AC6,$A:$A,"<=" &$AD6))-1 -> -0.031294681 | AI6: =EXP(SUMIFS(Z:Z,$A:$A,">=" &$AC6,$A:$A,"<=" &$AD6))-1 -> 0.080419302
A7: 40186 | B7: 22226.23 | C7: 22.39395 | D7: =B7/B6-1 -> -0.0022414097 | E7: =C7/C6-1 -> 0.00032832141 | G7: =IF(VLOOKUP(A7,Aux!B:C,2,FALSE)=0,"",VLOOKUP(A7,Aux!B:C,2,FALSE)) | H7: =IF(ISNUMBER(G7),1-G7,"") | L7: =L6+M7+N7 -> 101374.92 | M7: =O6*(B7-B6) -> -115.19026 | N7: =P6*(C7-C6) -> 16.442924 | O7: =IF(ISNUMBER(G7),L7*G7/B7,O6) -> 2.307035 | P7: =IF(ISNUMBER(H7),L7*H7/C7,P6) -> 2237.1325 | S7: =O7*B7/L7 -> 0.50581237 | T7: =P7*C7/L7 -> 0.49418763 | V7: =$O$2*B7+$P$2*C7 -> 101374.92 | W7: =LN(L7/L6) -> -0.00097360637 | X7: =LN(V7/V6) -> -0.00097360637 | Y7: =LN(B7/B6) -> -0.0022439254 | Z7: =LN(C7/C6) -> 0.00032826752 | AC7: =DATE(AE7,1,1) -> 41640 | AD7: =DATE(AE7+1,1,1)-1 -> 42004 | AE7: 2014 | AF7: =EXP(SUMIFS(W:W,$A:$A,">=" &$AC7,$A:$A,"<=" &$AD7))-1 -> 0.040101159 | AG7: =EXP(SUMIFS(X:X,$A:$A,">=" &$AC7,$A:$A,"<=" &$AD7))-1 -> 0.052798354 | AH7: =EXP(SUMIFS(Y:Y,$A:$A,">=" &$AC7,$A:$A,"<=" &$AD7))-1 -> -0.027794631 | AI7: =EXP(SUMIFS(Z:Z,$A:$A,">=" &$AC7,$A:$A,"<=" &$AD7))-1 -> 0.10799695
A8: 40189 | B8: 22259.32 | C8: 22.4013 | D8: =B8/B7-1 -> 0.0014887815 | E8: =C8/C7-1 -> 0.00032821365 | G8: =IF(VLOOKUP(A8,Aux!B:C,2,FALSE)=0,"",VLOOKUP(A8,Aux!B:C,2,FALSE)) | H8: =IF(ISNUMBER(G8),1-G8,"") | L8: =L7+M8+N8 -> 101467.71 | M8: =O7*(B8-B7) -> 76.339787 | N8: =P7*(C8-C7) -> 16.442924 | O8: =IF(ISNUMBER(G8),L8*G8/B8,O7) -> 2.307035 | P8: =IF(ISNUMBER(H8),L8*H8/C8,P7) -> 2237.1325 | S8: =O8*B8/L8 -> 0.50610221 | T8: =P8*C8/L8 -> 0.49389779 | V8: =$O$2*B8+$P$2*C8 -> 101467.71 | W8: =LN(L8/L7) -> 0.00091482465 | X8: =LN(V8/V7) -> 0.00091482465 | Y8: =LN(B8/B7) -> 0.0014876744 | Z8: =LN(C8/C7) -> 0.0003281598 | AC8: =DATE(AE8,1,1) -> 42005 | AD8: =DATE(AE8+1,1,1)-1 -> 42369 | AE8: 2015 | AF8: =EXP(SUMIFS(W:W,$A:$A,">=" &$AC8,$A:$A,"<=" &$AD8))-1 -> 0.0040489043 | AG8: =EXP(SUMIFS(X:X,$A:$A,">=" &$AC8,$A:$A,"<=" &$AD8))-1 -> 0.035986735 | AH8: =EXP(SUMIFS(Y:Y,$A:$A,">=" &$AC8,$A:$A,"<=" &$AD8))-1 -> -0.12408918 | AI8: =EXP(SUMIFS(Z:Z,$A:$A,">=" &$AC8,$A:$A,"<=" &$AD8))-1 -> 0.13218699
A9: 40190 | B9: 22158.28 | C9: 22.40865 | D9: =B9/B8-1 -> -0.0045392222 | E9: =C9/C8-1 -> 0.00032810596 | G9: =IF(VLOOKUP(A9,Aux!B:C,2,FALSE)=0,"",VLOOKUP(A9,Aux!B:C,2,FALSE)) | H9: =IF(ISNUMBER(G9),1-G9,"") | L9: =L8+M9+N9 -> 101251.05 | M9: =O8*(B9-B8) -> -233.10281 | N9: =P8*(C9-C8) -> 16.442924 | O9: =IF(ISNUMBER(G9),L9*G9/B9,O8) -> 2.307035 | P9: =IF(ISNUMBER(H9),L9*H9/C9,P8) -> 2237.1325 | S9: =O9*B9/L9 -> 0.50488296 | T9: =P9*C9/L9 -> 0.49511704 | V9: =$O$2*B9+$P$2*C9 -> 101251.05 | W9: =LN(L9/L8) -> -0.0021375425 | X9: =LN(V9/V8) -> -0.0021375425 | Y9: =LN(B9/B8) -> -0.0045495558 | Z9: =LN(C9/C8) -> 0.00032805214 | AC9: =DATE(AE9,1,1) -> 42370 | AD9: =DATE(AE9+1,1,1)-1 -> 42735 | AE9: 2016 | AF9: =EXP(SUMIFS(W:W,$A:$A,">=" &$AC9,$A:$A,"<=" &$AD9))-1 -> 0.25350058 | AG9: =EXP(SUMIFS(X:X,$A:$A,">=" &$AC9,$A:$A,"<=" &$AD9))-1 -> 0.21205617 | AH9: =EXP(SUMIFS(Y:Y,$A:$A,">=" &$AC9,$A:$A,"<=" &$AD9))-1 -> 0.36696966 | AI9: =EXP(SUMIFS(Z:Z,$A:$A,">=" &$AC9,$A:$A,"<=" &$AD9))-1 -> 0.14003151
A10: 40191 | B10: 22236.79 | C10: 22.416 | D10: =B10/B9-1 -> 0.003543145 | E10: =C10/C9-1 -> 0.00032799834 | G10: =IF(VLOOKUP(A10,Aux!B:C,2,FALSE)=0,"",VLOOKUP(A10,Aux!B:C,2,FALSE)) | H10: =IF(ISNUMBER(G10),1-G10,"") | L10: =L9+M10+N10 -> 101448.61 | M10: =O9*(B10-B9) -> 181.12532 | N10: =P9*(C10-C9) -> 16.442924 | O10: =IF(ISNUMBER(G10),L10*G10/B10,O9) -> 2.307035 | P10: =IF(ISNUMBER(H10),L10*H10/C10,P9) -> 2237.1325 | S10: =O10*B10/L10 -> 0.5056851 | T10: =P10*C10/L10 -> 0.4943149 | V10: =$O$2*B10+$P$2*C10 -> 101448.61 | W10: =LN(L10/L9) -> 0.0019493699 | X10: =LN(V10/V9) -> 0.0019493699 | Y10: =LN(B10/B9) -> 0.0035368829 | Z10: =LN(C10/C9) -> 0.00032794456 | AC10: =DATE(AE10,1,1) -> 42736 | AD10: =DATE(AE10+1,1,1)-1 -> 43100 | AE10: 2017 | AF10: =EXP(SUMIFS(W:W,$A:$A,">=" &$AC10,$A:$A,"<=" &$AD10))-1 -> 0.18762104 | AG10: =EXP(SUMIFS(X:X,$A:$A,">=" &$AC10,$A:$A,"<=" &$AD10))-1 -> 0.16266593 | AH10: =EXP(SUMIFS(Y:Y,$A:$A,">=" &$AC10,$A:$A,"<=" &$AD10))-1 -> 0.27545381 | AI10: =EXP(SUMIFS(Z:Z,$A:$A,">=" &$AC10,$A:$A,"<=" &$AD10))-1 -> 0.099788264
A11: 40192 | B11: 22046.74 | C11: 22.42336 | D11: =B11/B10-1 -> -0.0085466472 | E11: =C11/C10-1 -> 0.0003283369 | G11: =IF(VLOOKUP(A11,Aux!B:C,2,FALSE)=0,"",VLOOKUP(A11,Aux!B:C,2,FALSE)) | H11: =IF(ISNUMBER(G11),1-G11,"") | L11: =L10+M11+N11 -> 101026.63 | M11: =O10*(B11-B10) -> -438.452 | N11: =P10*(C11-C10) -> 16.465295 | O11: =IF(ISNUMBER(G11),L11*G11/B11,O10) -> 2.307035 | P11: =IF(ISNUMBER(H11),L11*H11/C11,P10) -> 2237.1325 | S11: =O11*B11/L11 -> 0.50345737 | T11: =P11*C11/L11 -> 0.49654263 | V11: =$O$2*B11+$P$2*C11 -> 101026.63 | W11: =LN(L11/L10) -> -0.0041682856 | X11: =LN(V11/V10) -> -0.0041682856 | Y11: =LN(B11/B10) -> -0.0085833793 | Z11: =LN(C11/C10) -> 0.00032828301 | AC11: =DATE(AE11,1,1) -> 43101 | AD11: =DATE(AE11+1,1,1)-1 -> 43465 | AE11: 2018 | AF11: =EXP(SUMIFS(W:W,$A:$A,">=" &$AC11,$A:$A,"<=" &$AD11))-1 -> 0.10922989 | AG11: =EXP(SUMIFS(X:X,$A:$A,">=" &$AC11,$A:$A,"<=" &$AD11))-1 -> 0.099574369 | AH11: =EXP(SUMIFS(Y:Y,$A:$A,">=" &$AC11,$A:$A,"<=" &$AD11))-1 -> 0.15420736 | AI11: =EXP(SUMIFS(Z:Z,$A:$A,">=" &$AC11,$A:$A,"<=" &$AD11))-1 -> 0.064252421
A12: 40193 | B12: 21809.1 | C12: 22.43072 | D12: =B12/B11-1 -> -0.010778918 | E12: =C12/C11-1 -> 0.00032822913 | G12: =IF(VLOOKUP(A12,Aux!B:C,2,FALSE)=0,"",VLOOKUP(A12,Aux!B:C,2,FALSE)) | H12: =IF(ISNUMBER(G12),1-G12,"") | L12: =L11+M12+N12 -> 100494.85 | M12: =O11*(B12-B11) -> -548.24379 | N12: =P11*(C12-C11) -> 16.465295 | O12: =IF(ISNUMBER(G12),L12*G12/B12,O11) -> 2.307035 | P12: =IF(ISNUMBER(H12),L12*H12/C12,P11) -> 2237.1325 | S12: =O12*B12/L12 -> 0.50066603 | T12: =P12*C12/L12 -> 0.49933397 | V12: =$O$2*B12+$P$2*C12 -> 100494.85 | W12: =LN(L12/L11) -> -0.0052776483 | X12: =LN(V12/V11) -> -0.0052776483 | Y12: =LN(B12/B11) -> -0.010837431 | Z12: =LN(C12/C11) -> 0.00032817528 | AC12: =DATE(AE12,1,1) -> 43466 | AD12: =DATE(AE12+1,1,1)-1 -> 43830 | AE12: 2019 | AF12: =EXP(SUMIFS(W:W,$A:$A,">=" &$AC12,$A:$A,"<=" &$AD12))-1 -> 0.19682244 | AG12: =EXP(SUMIFS(X:X,$A:$A,">=" &$AC12,$A:$A,"<=" &$AD12))-1 -> 0.17274638 | AH12: =EXP(SUMIFS(Y:Y,$A:$A,">=" &$AC12,$A:$A,"<=" &$AD12))-1 -> 0.33388671 | AI12: =EXP(SUMIFS(Z:Z,$A:$A,">=" &$AC12,$A:$A,"<=" &$AD12))-1 -> 0.059758179
A13: 40196 | B13: 21997.97 | C13: 22.43807 | D13: =B13/B12-1 -> 0.0086601465 | E13: =C13/C12-1 -> 0.00032767562 | G13: =IF(VLOOKUP(A13,Aux!B:C,2,FALSE)=0,"",VLOOKUP(A13,Aux!B:C,2,FALSE)) | H13: =IF(ISNUMBER(G13),1-G13,"") | L13: =L12+M13+N13 -> 100947.02 | M13: =O12*(B13-B12) -> 435.7297 | N13: =P12*(C13-C12) -> 16.442924 | O13: =IF(ISNUMBER(G13),L13*G13/B13,O12) -> 2.307035 | P13: =IF(ISNUMBER(H13),L13*H13/C13,P12) -> 2237.1325 | S13: =O13*B13/L13 -> 0.50273981 | T13: =P13*C13/L13 -> 0.49726019 | V13: =$O$2*B13+$P$2*C13 -> 100947.02 | W13: =LN(L13/L12) -> 0.0044893684 | X13: =LN(V13/V12) -> 0.0044893684 | Y13: =LN(B13/B12) -> 0.0086228625 | Z13: =LN(C13/C12) -> 0.00032762194 | AE13: Total | AF13: {=PRODUCT(AF3:AF12+1)-1} -> 1.4719173 | AG13: {=PRODUCT(AG3:AG12+1)-1} -> 1.3953567 | AH13: {=PRODUCT(AH3:AH12+1)-1} -> 1.2459179 | AI13: {=PRODUCT(AI3:AI12+1)-1} -> 1.5447955
A14: 40197 | B14: 22138.31 | C14: 22.44543 | D14: =B14/B13-1 -> 0.0063796796 | E14: =C14/C13-1 -> 0.00032801395 | G14: =IF(VLOOKUP(A14,Aux!B:C,2,FALSE)=0,"",VLOOKUP(A14,Aux!B:C,2,FALSE)) | H14: =IF(ISNUMBER(G14),1-G14,"") | L14: =L13+M14+N14 -> 101287.26 | M14: =O13*(B14-B13) -> 323.76929 | N14: =P13*(C14-C13) -> 16.465295 | O14: =IF(ISNUMBER(G14),L14*G14/B14,O13) -> 2.307035 | P14: =IF(ISNUMBER(H14),L14*H14/C14,P13) -> 2237.1325 | S14: =O14*B14/L14 -> 0.5042476 | T14: =P14*C14/L14 -> 0.4957524 | V14: =$O$2*B14+$P$2*C14 -> 101287.26 | W14: =LN(L14/L13) -> 0.00336476 | X14: =LN(V14/V13) -> 0.00336476 | Y14: =LN(B14/B13) -> 0.0063594156 | Z14: =LN(C14/C13) -> 0.00032796017 | AG14: =50%*AH13+50%*AI13 -> 1.3953567
A15: 40198 | B15: 21614.96 | C15: 22.45278 | D15: =B15/B14-1 -> -0.023640016 | E15: =C15/C14-1 -> 0.00032746087 | G15: =IF(VLOOKUP(A15,Aux!B:C,2,FALSE)=0,"",VLOOKUP(A15,Aux!B:C,2,FALSE)) | H15: =IF(ISNUMBER(G15),1-G15,"") | L15: =L14+M15+N15 -> 100096.31 | M15: =O14*(B15-B14) -> -1207.3868 | N15: =P14*(C15-C14) -> 16.442924 | O15: =IF(ISNUMBER(G15),L15*G15/B15,O14) -> 2.307035 | P15: =IF(ISNUMBER(H15),L15*H15/C15,P14) -> 2237.1325 | S15: =O15*B15/L15 -> 0.49818488 | T15: =P15*C15/L15 -> 0.50181512 | V15: =$O$2*B15+$P$2*C15 -> 100096.31 | W15: =LN(L15/L14) -> -0.011827755 | X15: =LN(V15/V14) -> -0.011827755 | Y15: =LN(B15/B14) -> -0.023923924 | Z15: =LN(C15/C14) -> 0.00032740726
A16: 40199 | B16: 21042.6 | C16: 22.46015 | D16: =B16/B15-1 -> -0.026479808 | E16: =C16/C15-1 -> 0.00032824443 | G16: =IF(VLOOKUP(A16,Aux!B:C,2,FALSE)=0,"",VLOOKUP(A16,Aux!B:C,2,FALSE)) | H16: =IF(ISNUMBER(G16),1-G16,"") | L16: =L15+M16+N16 -> 98792.345 | M16: =O15*(B16-B15) -> -1320.4545 | N16: =P15*(C16-C15) -> 16.487666 | O16: =IF(ISNUMBER(G16),L16*G16/B16,O15) -> 2.307035 | P16: =IF(ISNUMBER(H16),L16*H16/C16,P15) -> 2237.1325 | S16: =O16*B16/L16 -> 0.49139449 | T16: =P16*C16/L16 -> 0.50860551 | V16: =$O$2*B16+$P$2*C16 -> 98792.345 | W16: =LN(L16/L15) -> -0.013112719 | X16: =LN(V16/V15) -> -0.013112719 | Y16: =LN(B16/B15) -> -0.026836713 | Z16: =LN(C16/C15) -> 0.00032819057
A17: 40200 | B17: 21051.16 | C17: 22.46752 | D17: =B17/B16-1 -> 0.00040679384 | E17: =C17/C16-1 -> 0.00032813672 | G17: =IF(VLOOKUP(A17,Aux!B:C,2,FALSE)=0,"",VLOOKUP(A17,Aux!B:C,2,FALSE)) | H17: =IF(ISNUMBER(G17),1-G17,"") | L17: =L16+M17+N17 -> 98828.581 | M17: =O16*(B17-B16) -> 19.748219 | N17: =P16*(C17-C16) -> 16.487666 | O17: =IF(ISNUMBER(G17),L17*G17/B17,O16) -> 2.307035 | P17: =IF(ISNUMBER(H17),L17*H17/C17,P16) -> 2237.1325 | S17: =O17*B17/L17 -> 0.49141414 | T17: =P17*C17/L17 -> 0.50858586 | V17: =$O$2*B17+$P$2*C17 -> 98828.581 | W17: =LN(L17/L16) -> 0.00036672114 | X17: =LN(V17/V16) -> 0.00036672114 | Y17: =LN(B17/B16) -> 0.00040671112 | Z17: =LN(C17/C16) -> 0.0003280829
A18: 40204 | B18: 20823.6 | C18: 22.48227 | D18: =B18/B17-1 -> -0.010809856 | E18: =C18/C17-1 -> 0.00065650325 | G18: =IF(VLOOKUP(A18,Aux!B:C,2,FALSE)=0,"",VLOOKUP(A18,Aux!B:C,2,FALSE)) | H18: =IF(ISNUMBER(G18),1-G18,"") | L18: =L17+M18+N18 -> 98336.59 | M18: =O17*(B18-B17) -> -524.98888 | N18: =P17*(C18-C17) -> 32.997704 | O18: =IF(ISNUMBER(G18),L18*G18/B18,O17) -> 2.307035 | P18: =IF(ISNUMBER(H18),L18*H18/C18,P17) -> 2237.1325 | S18: =O18*B18/L18 -> 0.48853406 | T18: =P18*C18/L18 -> 0.51146594 | V18: =$O$2*B18+$P$2*C18 -> 98336.59 | W18: =LN(L18/L17) -> -0.0049906603 | X18: =LN(V18/V17) -> -0.0049906603 | Y18: =LN(B18/B17) -> -0.010868707 | Z18: =LN(C18/C17) -> 0.00065628785
A19: 40205 | B19: 20660.46 | C19: 22.48965 | D19: =B19/B18-1 -> -0.0078343802 | E19: =C19/C18-1 -> 0.00032825867 | G19: =IF(VLOOKUP(A19,Aux!B:C,2,FALSE)=0,"",VLOOKUP(A19,Aux!B:C,2,FALSE)) | H19: =IF(ISNUMBER(G19),1-G19,"") | L19: =L18+M19+N19 -> 97976.73 | M19: =O18*(B19-B18) -> -376.36969 | N19: =P18*(C19-C18) -> 16.510038 | O19: =IF(ISNUMBER(G19),L19*G19/B19,O18) -> 2.307035 | P19: =IF(ISNUMBER(H19),L19*H19/C19,P18) -> 2237.1325 | S19: =O19*B19/L19 -> 0.48648698 | T19: =P19*C19/L19 -> 0.51351302 | V19: =$O$2*B19+$P$2*C19 -> 97976.73 | W19: =LN(L19/L18) -> -0.0036661807 | X19: =LN(V19/V18) -> -0.0036661807 | Y19: =LN(B19/B18) -> -0.0078652302 | Z19: =LN(C19/C18) -> 0.0003282048
A20: 40206 | B20: 20870.99 | C20: 22.49703 | D20: =B20/B19-1 -> 0.010189996 | E20: =C20/C19-1 -> 0.00032815095 | G20: =IF(VLOOKUP(A20,Aux!B:C,2,FALSE)=0,"",VLOOKUP(A20,Aux!B:C,2,FALSE)) | H20: =IF(ISNUMBER(G20),1-G20,"") | L20: =L19+M20+N20 -> 98478.94 | M20: =O19*(B20-B19) -> 485.70007 | N20: =P19*(C20-C19) -> 16.510038 | O20: =IF(ISNUMBER(G20),L20*G20/B20,O19) -> 2.307035 | P20: =IF(ISNUMBER(H20),L20*H20/C20,P19) -> 2237.1325 | S20: =O20*B20/L20 -> 0.48893808 | T20: =P20*C20/L20 -> 0.51106192 | V20: =$O$2*B20+$P$2*C20 -> 98478.94 | W20: =LN(L20/L19) -> 0.0051127179 | X20: =LN(V20/V19) -> 0.0051127179 | Y20: =LN(B20/B19) -> 0.010138428 | Z20: =LN(C20/C19) -> 0.00032809712
A21: 40207 | B21: 20758 | C21: 22.50441 | D21: =B21/B20-1 -> -0.0054137346 | E21: =C21/C20-1 -> 0.0003280433 | G21: =IF(VLOOKUP(A21,Aux!B:C,2,FALSE)=0,"",VLOOKUP(A21,Aux!B:C,2,FALSE)) | H21: =IF(ISNUMBER(G21),1-G21,"") | L21: =L20+M21+N21 -> 98234.778 | M21: =O20*(B21-B20) -> -260.67188 | N21: =P20*(C21-C20) -> 16.510038 | O21: =IF(ISNUMBER(G21),L21*G21/B21,O20) -> 2.307035 | P21: =IF(ISNUMBER(H21),L21*H21/C21,P20) -> 2237.1325 | S21: =O21*B21/L21 -> 0.48749977 | T21: =P21*C21/L21 -> 0.51250023 | V21: =$O$2*B21+$P$2*C21 -> 98234.778 | W21: =LN(L21/L20) -> -0.0024824092 | X21: =LN(V21/V20) -> -0.0024824092 | Y21: =LN(B21/B20) -> -0.0054284419 | Z21: =LN(C21/C20) -> 0.00032798951
A22: 40210 | B22: 21081.95 | C22: 22.5118 | D22: =B22/B21-1 -> 0.015606031 | E22: =C22/C21-1 -> 0.00032838008 | G22: =IF(VLOOKUP(A22,Aux!B:C,2,FALSE)=0,"",VLOOKUP(A22,Aux!B:C,2,FALSE)) | H22: =IF(ISNUMBER(G22),1-G22,"") | L22: =L21+M22+N22 -> 98998.675 | M22: =O21*(B22-B21) -> 747.36398 | N22: =P21*(C22-C21) -> 16.532409 | O22: =IF(ISNUMBER(G22),L22*G22/B22,O21) -> 2.307035 | P22: =IF(ISNUMBER(H22),L22*H22/C22,P21) -> 2237.1325 | S22: =O22*B22/L22 -> 0.49128735 | T22: =P22*C22/L22 -> 0.50871265 | V22: =$O$2*B22+$P$2*C22 -> 98998.675 | W22: =LN(L22/L21) -> 0.0077461526 | X22: =LN(V22/V21) -> 0.0077461526 | Y22: =LN(B22/B21) -> 0.01548551 | Z22: =LN(C22/C21) -> 0.00032832618
A23: 40211 | B23: 21231.16 | C23: 22.5192 | D23: =B23/B22-1 -> 0.0070776185 | E23: =C23/C22-1 -> 0.0003287165 | G23: =IF(VLOOKUP(A23,Aux!B:C,2,FALSE)=0,"",VLOOKUP(A23,Aux!B:C,2,FALSE)) | H23: =IF(ISNUMBER(G23),1-G23,"") | L23: =L22+M23+N23 -> 99359.462 | M23: =O22*(B23-B22) -> 344.23269 | N23: =P22*(C23-C22) -> 16.55478 | O23: =IF(ISNUMBER(G23),L23*G23/B23,O22) -> 2.307035 | P23: =IF(ISNUMBER(H23),L23*H23/C23,P22) -> 2237.1325 | S23: =O23*B23/L23 -> 0.49296793 | T23: =P23*C23/L23 -> 0.50703207 | V23: =$O$2*B23+$P$2*C23 -> 99359.462 | W23: =LN(L23/L22) -> 0.003637742 | X23: =LN(V23/V22) -> 0.003637742 | Y23: =LN(B23/B22) -> 0.0070526897 | Z23: =LN(C23/C22) -> 0.00032866248
A24: 40212 | B24: 21234.27 | C24: 22.52659 | D24: =B24/B23-1 -> 0.00014648281 | E24: =C24/C23-1 -> 0.00032816441 | G24: =IF(VLOOKUP(A24,Aux!B:C,2,FALSE)=0,"",VLOOKUP(A24,Aux!B:C,2,FALSE)) | H24: =IF(ISNUMBER(G24),1-G24,"") | L24: =L23+M24+N24 -> 99383.169 | M24: =O23*(B24-B23) -> 7.1748788 | N24: =P23*(C24-C23) -> 16.532409 | O24: =IF(ISNUMBER(G24),L24*G24/B24,O23) -> 2.307035 | P24: =IF(ISNUMBER(H24),L24*H24/C24,P23) -> 2237.1325 | S24: =O24*B24/L24 -> 0.49292253 | T24: =P24*C24/L24 -> 0.50707747 | V24: =$O$2*B24+$P$2*C24 -> 99383.169 | W24: =LN(L24/L23) -> 0.00023857275 | X24: =LN(V24/V23) -> 0.00023857275 | Y24: =LN(B24/B23) -> 0.00014647208 | Z24: =LN(C24/C23) -> 0.00032811058
A25: 40213 | B25: 20289.62 | C25: 22.53398 | D25: =B25/B24-1 -> -0.044487049 | E25: =C25/C24-1 -> 0.00032805675 | G25: =IF(VLOOKUP(A25,Aux!B:C,2,FALSE)=0,"",VLOOKUP(A25,Aux!B:C,2,FALSE)) | H25: =IF(ISNUMBER(G25),1-G25,"") | L25: =L24+M25+N25 -> 97220.361 | M25: =O24*(B25-B24) -> -2179.3406 | N25: =P24*(C25-C24) -> 16.532409 | O25: =IF(ISNUMBER(G25),L25*G25/B25,O24) -> 2.307035 | P25: =IF(ISNUMBER(H25),L25*H25/C25,P24) -> 2237.1325 | S25: =O25*B25/L25 -> 0.48147181 | T25: =P25*C25/L25 -> 0.51852819 | V25: =$O$2*B25+$P$2*C25 -> 97220.361 | W25: =LN(L25/L24) -> -0.02200261 | X25: =LN(V25/V24) -> -0.02200261 | Y25: =LN(B25/B24) -> -0.045506961 | Z25: =LN(C25/C24) -> 0.00032800296
A26: 40214 | B26: 19896.73 | C26: 22.54137 | D26: =B26/B25-1 -> -0.019364089 | E26: =C26/C25-1 -> 0.00032794917 | G26: =IF(VLOOKUP(A26,Aux!B:C,2,FALSE)=0,"",VLOOKUP(A26,Aux!B:C,2,FALSE)) | H26: =IF(ISNUMBER(G26),1-G26,"") | L26: =L25+M26+N26 -> 96330.483 | M26: =O25*(B26-B25) -> -906.41097 | N26: =P25*(C26-C25) -> 16.532409 | O26: =IF(ISNUMBER(G26),L26*G26/B26,O25) -> 2.307035 | P26: =IF(ISNUMBER(H26),L26*H26/C26,P25) -> 2237.1325 | S26: =O26*B26/L26 -> 0.47651014 | T26: =P26*C26/L26 -> 0.52348986 | V26: =$O$2*B26+$P$2*C26 -> 96330.483 | W26: =LN(L26/L25) -> -0.0091953599 | X26: =LN(V26/V25) -> -0.0091953599 | Y26: =LN(B26/B25) -> -0.019554029 | Z26: =LN(C26/C25) -> 0.0003278954
... A2474: 43829 | B2474: 48675.42 | C2474: 56.876282 | D2474: =B2474/B2473-1 -> -0.0066255007 | E2474: =C2474/C2473-1 -> 0.00017092294 | G2474: =IF(VLOOKUP(A2474,Aux!B:C,2,FALSE)=0,"",VLOOKUP(A2474,Aux!B:C,2,FALSE)) -> 0.5 | H2474: =IF(ISNUMBER(G2474),1-G2474,"") -> 0.5 | L2474: =L2473+M2474+N2474 -> 247191.73 | M2474: =O2473*(B2474-B2473) -> -918.75318 | N2474: =P2473*(C2474-C2473) -> 18.702821 | O2474: =IF(ISNUMBER(G2474),L2474*G2474/B2474,O2473) -> 2.5391843 | P2474: =IF(ISNUMBER(H2474),L2474*H2474/C2474,P2473) -> 2173.0651 | S2474: =O2474*B2474/L2474 -> 0.5 | T2474: =P2474*C2474/L2474 -> 0.5 | V2474: =$O$2*B2474+$P$2*C2474 -> 239535.67 | W2474: =LN(L2474/L2473) -> -0.0036344895 | X2474: =LN(V2474/V2473) -> -0.0030314178 | Y2474: =LN(B2474/B2473) -> -0.0066475468 | Z2474: =LN(C2474/C2473) -> 0.00017090834

Sheet Aux
A1: =Rebalance!AG1 -> Anual | C1: Periodo | D1: Diario | E1: Mensal | F1: Trimestral | G1: Semestral | H1: Anual
B2: 40177 | C2: =INDEX(D2:H2,MATCH($A$1,$D$1:$H$1,0)) -> 0.5 | D2: 0.5 | E2: 0.5 | F2: 0.5 | G2: 0.5 | H2: 0.5
B3: 40182 | C3: =INDEX(D3:H3,MATCH($A$1,$D$1:$H$1,0)) | D3: 0.5
B4: 40183 | C4: =INDEX(D4:H4,MATCH($A$1,$D$1:$H$1,0)) | D4: 0.5
B5: 40184 | C5: =INDEX(D5:H5,MATCH($A$1,$D$1:$H$1,0)) | D5: 0.5
B6: 40185 | C6: =INDEX(D6:H6,MATCH($A$1,$D$1:$H$1,0)) | D6: 0.5
B7: 40186 | C7: =INDEX(D7:H7,MATCH($A$1,$D$1:$H$1,0)) | D7: 0.5
B8: 40189 | C8: =INDEX(D8:H8,MATCH($A$1,$D$1:$H$1,0)) | D8: 0.5
B9: 40190 | C9: =INDEX(D9:H9,MATCH($A$1,$D$1:$H$1,0)) | D9: 0.5
B10: 40191 | C10: =INDEX(D10:H10,MATCH($A$1,$D$1:$H$1,0)) | D10: 0.5
B11: 40192 | C11: =INDEX(D11:H11,MATCH($A$1,$D$1:$H$1,0)) | D11: 0.5
B12: 40193 | C12: =INDEX(D12:H12,MATCH($A$1,$D$1:$H$1,0)) | D12: 0.5
B13: 40196 | C13: =INDEX(D13:H13,MATCH($A$1,$D$1:$H$1,0)) | D13: 0.5
B14: 40197 | C14: =INDEX(D14:H14,MATCH($A$1,$D$1:$H$1,0)) | D14: 0.5
... B20: 40206 | C20: =INDEX(D20:H20,MATCH($A$1,$D$1:$H$1,0)) | D20: 0.5
B21: 40207 | C21: =INDEX(D21:H21,MATCH($A$1,$D$1:$H$1,0)) | D21: 0.5 | E21: 0.5
B22: 40210 | C22: =INDEX(D22:H22,MATCH($A$1,$D$1:$H$1,0)) | D22: 0.5
B23: 40211 | C23: =INDEX(D23:H23,MATCH($A$1,$D$1:$H$1,0)) | D23: 0.5
B24: 40212 | C24: =INDEX(D24:H24,MATCH($A$1,$D$1:$H$1,0)) | D24: 0.5
B25: 40213 | C25: =INDEX(D25:H25,MATCH($A$1,$D$1:$H$1,0)) | D25: 0.5
B26: 40214 | C26: =INDEX(D26:H26,MATCH($A$1,$D$1:$H$1,0)) | D26: 0.5
B27: 40217 | C27: =INDEX(D27:H27,MATCH($A$1,$D$1:$H$1,0)) | D27: 0.5
B28: 40218 | C28: =INDEX(D28:H28,MATCH($A$1,$D$1:$H$1,0)) | D28: 0.5
B29: 40219 | C29: =INDEX(D29:H29,MATCH($A$1,$D$1:$H$1,0)) | D29: 0.5
B30: 40220 | C30: =INDEX(D30:H30,MATCH($A$1,$D$1:$H$1,0)) | D30: 0.5
B31: 40221 | C31: =INDEX(D31:H31,MATCH($A$1,$D$1:$H$1,0)) | D31: 0.5
B32: 40226 | C32: =INDEX(D32:H32,MATCH($A$1,$D$1:$H$1,0)) | D32: 0.5
B33: 40227 | C33: =INDEX(D33:H33,MATCH($A$1,$D$1:$H$1,0)) | D33: 0.5
... B38: 40234 | C38: =INDEX(D38:H38,MATCH($A$1,$D$1:$H$1,0)) | D38: 0.5
B39: 40235 | C39: =INDEX(D39:H39,MATCH($A$1,$D$1:$H$1,0)) | D39: 0.5 | E39: 0.5
B40: 40238 | C40: =INDEX(D40:H40,MATCH($A$1,$D$1:$H$1,0)) | D40: 0.5
B41: 40239 | C41: =INDEX(D41:H41,MATCH($A$1,$D$1:$H$1,0)) | D41: 0.5
B42: 40240 | C42: =INDEX(D42:H42,MATCH($A$1,$D$1:$H$1,0)) | D42: 0.5
B43: 40241 | C43: =INDEX(D43:H43,MATCH($A$1,$D$1:$H$1,0)) | D43: 0.5
B44: 40242 | C44: =INDEX(D44:H44,MATCH($A$1,$D$1:$H$1,0)) | D44: 0.5
B45: 40245 | C45: =INDEX(D45:H45,MATCH($A$1,$D$1:$H$1,0)) | D45: 0.5
B46: 40246 | C46: =INDEX(D46:H46,MATCH($A$1,$D$1:$H$1,0)) | D46: 0.5
B47: 40247 | C47: =INDEX(D47:H47,MATCH($A$1,$D$1:$H$1,0)) | D47: 0.5
B48: 40248 | C48: =INDEX(D48:H48,MATCH($A$1,$D$1:$H$1,0)) | D48: 0.5
B49: 40249 | C49: =INDEX(D49:H49,MATCH($A$1,$D$1:$H$1,0)) | D49: 0.5
...
