Workbook
Name Avg: OFFSET(Exemplo_Serie!$F$2,Exemplo_Serie!$K$1-1,0,COUNTIFS(Exemplo_Serie!$F:$F,">0"))
Name Data: OFFSET(Exemplo_Serie!$A$2,Exemplo_Serie!$K$1-1,0,COUNTIFS(Exemplo_Serie!$F:$F,">0"))
Name Desvio_Mais: OFFSET(Exemplo_Serie!$G$2,Exemplo_Serie!$K$1-1,0,COUNTIFS(Exemplo_Serie!$F:$F,">0"))
Name Desvio_menos: OFFSET(Exemplo_Serie!$H$2,Exemplo_Serie!$K$1-1,0,COUNTIFS(Exemplo_Serie!$F:$F,">0"))
Name Razao: OFFSET(Exemplo_Serie!$E$2,Exemplo_Serie!$K$1-1,0,COUNTIFS(Exemplo_Serie!$F:$F,">0"))

Sheet Exemplo_Serie
A1: Data | B1: PETR4 | C1: PETR3 | E1: =B1 & "/" & C1 -> PETR4/PETR3 | F1: Avg | G1: ="+" &M1 & "std" -> +1std | H1: ="-" &M1 & "std" -> -1std | I1: Desvios | J1: Dias | K1: 30 | L1: ndesvios | M1: 1
A2: 41334 | B2: 14.430294 | C2: 13.313787 | E2: =IF(ISNUMBER(B2),B2/C2,"") -> 1.083861 | F2: =IF(ISNUMBER(E2),IF(ROW(E2)>$K$1,AVERAGE(OFFSET(E2,0,0,-$K$1)),""),"") | G2: =IF(ISNUMBER(I2),F2+I2*$M$1,"") | H2: =IF(ISNUMBER(I2),F2-I2*$M$1,"") | I2: =IF(ISNUMBER(E2),IF(ROW(E2)>$K$1,_xlfn.STDEV.P(OFFSET(E2,0,0,-$K$1)),""),"")
A3: 41337 | B3: 14.088748 | C3: 12.905666 | E3: =IF(ISNUMBER(B3),B3/C3,"") -> 1.0916715 | F3: =IF(ISNUMBER(E3),IF(ROW(E3)>$K$1,AVERAGE(OFFSET(E3,0,0,-$K$1)),""),"") | G3: =IF(ISNUMBER(I3),F3+I3*$M$1,"") | H3: =IF(ISNUMBER(I3),F3-I3*$M$1,"") | I3: =IF(ISNUMBER(E3),IF(ROW(E3)>$K$1,_xlfn.STDEV.P(OFFSET(E3,0,0,-$K$1)),""),"")
A4: 41338 | B4: 14.13998 | C4: 12.923804 | E4: =IF(ISNUMBER(B4),B4/C4,"") -> 1.0941036 | F4: =IF(ISNUMBER(E4),IF(ROW(E4)>$K$1,AVERAGE(OFFSET(E4,0,0,-$K$1)),""),"") | G4: =IF(ISNUMBER(I4),F4+I4*$M$1,"") | H4: =IF(ISNUMBER(I4),F4-I4*$M$1,"") | I4: =IF(ISNUMBER(E4),IF(ROW(E4)>$K$1,_xlfn.STDEV.P(OFFSET(E4,0,0,-$K$1)),""),"")
A5: 41339 | B5: 15.412234 | C5: 14.882782 | E5: =IF(ISNUMBER(B5),B5/C5,"") -> 1.0355748 | F5: =IF(ISNUMBER(E5),IF(ROW(E5)>$K$1,AVERAGE(OFFSET(E5,0,0,-$K$1)),""),"") | G5: =IF(ISNUMBER(I5),F5+I5*$M$1,"") | H5: =IF(ISNUMBER(I5),F5-I5*$M$1,"") | I5: =IF(ISNUMBER(E5),IF(ROW(E5)>$K$1,_xlfn.STDEV.P(OFFSET(E5,0,0,-$K$1)),""),"")
A6: 41340 | B6: 16.180714 | C6: 15.617395 | E6: =IF(ISNUMBER(B6),B6/C6,"") -> 1.03607 | F6: =IF(ISNUMBER(E6),IF(ROW(E6)>$K$1,AVERAGE(OFFSET(E6,0,0,-$K$1)),""),"") | G6: =IF(ISNUMBER(I6),F6+I6*$M$1,"") | H6: =IF(ISNUMBER(I6),F6-I6*$M$1,"") | I6: =IF(ISNUMBER(E6),IF(ROW(E6)>$K$1,_xlfn.STDEV.P(OFFSET(E6,0,0,-$K$1)),""),"")
A7: 41341 | B7: 15.685473 | C7: 15.145793 | E7: =IF(ISNUMBER(B7),B7/C7,"") -> 1.0356323 | F7: =IF(ISNUMBER(E7),IF(ROW(E7)>$K$1,AVERAGE(OFFSET(E7,0,0,-$K$1)),""),"") | G7: =IF(ISNUMBER(I7),F7+I7*$M$1,"") | H7: =IF(ISNUMBER(I7),F7-I7*$M$1,"") | I7: =IF(ISNUMBER(E7),IF(ROW(E7)>$K$1,_xlfn.STDEV.P(OFFSET(E7,0,0,-$K$1)),""),"")
A8: 41344 | B8: 16.163637 | C8: 15.59019 | E8: =IF(ISNUMBER(B8),B8/C8,"") -> 1.0367826 | F8: =IF(ISNUMBER(E8),IF(ROW(E8)>$K$1,AVERAGE(OFFSET(E8,0,0,-$K$1)),""),"") | G8: =IF(ISNUMBER(I8),F8+I8*$M$1,"") | H8: =IF(ISNUMBER(I8),F8-I8*$M$1,"") | I8: =IF(ISNUMBER(E8),IF(ROW(E8)>$K$1,_xlfn.STDEV.P(OFFSET(E8,0,0,-$K$1)),""),"")
A9: 41345 | B9: 16.0014 | C9: 15.363457 | E9: =IF(ISNUMBER(B9),B9/C9,"") -> 1.0415234 | F9: =IF(ISNUMBER(E9),IF(ROW(E9)>$K$1,AVERAGE(OFFSET(E9,0,0,-$K$1)),""),"") | G9: =IF(ISNUMBER(I9),F9+I9*$M$1,"") | H9: =IF(ISNUMBER(I9),F9-I9*$M$1,"") | I9: =IF(ISNUMBER(E9),IF(ROW(E9)>$K$1,_xlfn.STDEV.P(OFFSET(E9,0,0,-$K$1)),""),"")
A10: 41346 | B10: 16.009941 | C10: 15.327184 | E10: =IF(ISNUMBER(B10),B10/C10,"") -> 1.0445455 | F10: =IF(ISNUMBER(E10),IF(ROW(E10)>$K$1,AVERAGE(OFFSET(E10,0,0,-$K$1)),""),"") | G10: =IF(ISNUMBER(I10),F10+I10*$M$1,"") | H10: =IF(ISNUMBER(I10),F10-I10*$M$1,"") | I10: =IF(ISNUMBER(E10),IF(ROW(E10)>$K$1,_xlfn.STDEV.P(OFFSET(E10,0,0,-$K$1)),""),"")
A11: 41347 | B11: 16.471022 | C11: 15.807855 | E11: =IF(ISNUMBER(B11),B11/C11,"") -> 1.0419517 | F11: =IF(ISNUMBER(E11),IF(ROW(E11)>$K$1,AVERAGE(OFFSET(E11,0,0,-$K$1)),""),"") | G11: =IF(ISNUMBER(I11),F11+I11*$M$1,"") | H11: =IF(ISNUMBER(I11),F11-I11*$M$1,"") | I11: =IF(ISNUMBER(E11),IF(ROW(E11)>$K$1,_xlfn.STDEV.P(OFFSET(E11,0,0,-$K$1)),""),"")
A12: 41348 | B12: 16.300253 | C12: 16.143421 | E12: =IF(ISNUMBER(B12),B12/C12,"") -> 1.0097149 | F12: =IF(ISNUMBER(E12),IF(ROW(E12)>$K$1,AVERAGE(OFFSET(E12,0,0,-$K$1)),""),"") | G12: =IF(ISNUMBER(I12),F12+I12*$M$1,"") | H12: =IF(ISNUMBER(I12),F12-I12*$M$1,"") | I12: =IF(ISNUMBER(E12),IF(ROW(E12)>$K$1,_xlfn.STDEV.P(OFFSET(E12,0,0,-$K$1)),""),"")
A13: 41351 | B13: 16.394178 | C13: 15.989244 | E13: =IF(ISNUMBER(B13),B13/C13,"") -> 1.0253254 | F13: =IF(ISNUMBER(E13),IF(ROW(E13)>$K$1,AVERAGE(OFFSET(E13,0,0,-$K$1)),""),"") | G13: =IF(ISNUMBER(I13),F13+I13*$M$1,"") | H13: =IF(ISNUMBER(I13),F13-I13*$M$1,"") | I13: =IF(ISNUMBER(E13),IF(ROW(E13)>$K$1,_xlfn.STDEV.P(OFFSET(E13,0,0,-$K$1)),""),"")
... A213: 41645 | B213: 14.460304 | C213: 14.333049 | E213: =IF(ISNUMBER(B213),B213/C213,"") -> 1.0088784 | F213: =IF(ISNUMBER(E213),IF(ROW(E213)>$K$1,AVERAGE(OFFSET(E213,0,0,-$K$1)),""),"") -> 1.0121324 | G213: =IF(ISNUMBER(I213),F213+I213*$M$1,"") -> 1.0232863 | H213: =IF(ISNUMBER(I213),F213-I213*$M$1,"") -> 1.0009785 | I213: =IF(ISNUMBER(E213),IF(ROW(E213)>$K$1,_xlfn.STDEV.P(OFFSET(E213,0,0,-$K$1)),""),"") -> 0.01115387
E214: =IF(ISNUMBER(B214),B214/C214,"") | F214: =IF(ISNUMBER(E214),IF(ROW(E214)>$K$1,AVERAGE(OFFSET(E214,0,0,-$K$1)),""),"") | G214: =IF(ISNUMBER(I214),F214+I214*$M$1,"") | H214: =IF(ISNUMBER(I214),F214-I214*$M$1,"") | I214: =IF(ISNUMBER(E214),IF(ROW(E214)>$K$1,_xlfn.STDEV.P(OFFSET(E214,0,0,-$K$1)),""),"")
E215: =IF(ISNUMBER(B215),B215/C215,"") | F215: =IF(ISNUMBER(E215),IF(ROW(E215)>$K$1,AVERAGE(OFFSET(E215,0,0,-$K$1)),""),"") | G215: =IF(ISNUMBER(I215),F215+I215*$M$1,"") | H215: =IF(ISNUMBER(I215),F215-I215*$M$1,"") | I215: =IF(ISNUMBER(E215),IF(ROW(E215)>$K$1,_xlfn.STDEV.P(OFFSET(E215,0,0,-$K$1)),""),"")
E216: =IF(ISNUMBER(B216),B216/C216,"") | F216: =IF(ISNUMBER(E216),IF(ROW(E216)>$K$1,AVERAGE(OFFSET(E216,0,0,-$K$1)),""),"") | G216: =IF(ISNUMBER(I216),F216+I216*$M$1,"") | H216: =IF(ISNUMBER(I216),F216-I216*$M$1,"") | I216: =IF(ISNUMBER(E216),IF(ROW(E216)>$K$1,_xlfn.STDEV.P(OFFSET(E216,0,0,-$K$1)),""),"")
E217: =IF(ISNUMBER(B217),B217/C217,"") | F217: =IF(ISNUMBER(E217),IF(ROW(E217)>$K$1,AVERAGE(OFFSET(E217,0,0,-$K$1)),""),"") | G217: =IF(ISNUMBER(I217),F217+I217*$M$1,"") | H217: =IF(ISNUMBER(I217),F217-I217*$M$1,"") | I217: =IF(ISNUMBER(E217),IF(ROW(E217)>$K$1,_xlfn.STDEV.P(OFFSET(E217,0,0,-$K$1)),""),"")
E218: =IF(ISNUMBER(B218),B218/C218,"") | F218: =IF(ISNUMBER(E218),IF(ROW(E218)>$K$1,AVERAGE(OFFSET(E218,0,0,-$K$1)),""),"") | G218: =IF(ISNUMBER(I218),F218+I218*$M$1,"") | H218: =IF(ISNUMBER(I218),F218-I218*$M$1,"") | I218: =IF(ISNUMBER(E218),IF(ROW(E218)>$K$1,_xlfn.STDEV.P(OFFSET(E218,0,0,-$K$1)),""),"")
E219: =IF(ISNUMBER(B219),B219/C219,"") | F219: =IF(ISNUMBER(E219),IF(ROW(E219)>$K$1,AVERAGE(OFFSET(E219,0,0,-$K$1)),""),"") | G219: =IF(ISNUMBER(I219),F219+I219*$M$1,"") | H219: =IF(ISNUMBER(I219),F219-I219*$M$1,"") | I219: =IF(ISNUMBER(E219),IF(ROW(E219)>$K$1,_xlfn.STDEV.P(OFFSET(E219,0,0,-$K$1)),""),"")
E220: =IF(ISNUMBER(B220),B220/C220,"") | F220: =IF(ISNUMBER(E220),IF(ROW(E220)>$K$1,AVERAGE(OFFSET(E220,0,0,-$K$1)),""),"") | G220: =IF(ISNUMBER(I220),F220+I220*$M$1,"") | H220: =IF(ISNUMBER(I220),F220-I220*$M$1,"") | I220: =IF(ISNUMBER(E220),IF(ROW(E220)>$K$1,_xlfn.STDEV.P(OFFSET(E220,0,0,-$K$1)),""),"")
E221: =IF(ISNUMBER(B221),B221/C221,"") | F221: =IF(ISNUMBER(E221),IF(ROW(E221)>$K$1,AVERAGE(OFFSET(E221,0,0,-$K$1)),""),"") | G221: =IF(ISNUMBER(I221),F221+I221*$M$1,"") | H221: =IF(ISNUMBER(I221),F221-I221*$M$1,"") | I221: =IF(ISNUMBER(E221),IF(ROW(E221)>$K$1,_xlfn.STDEV.P(OFFSET(E221,0,0,-$K$1)),""),"")
E222: =IF(ISNUMBER(B222),B222/C222,"") | F222: =IF(ISNUMBER(E222),IF(ROW(E222)>$K$1,AVERAGE(OFFSET(E222,0,0,-$K$1)),""),"") | G222: =IF(ISNUMBER(I222),F222+I222*$M$1,"") | H222: =IF(ISNUMBER(I222),F222-I222*$M$1,"") | I222: =IF(ISNUMBER(E222),IF(ROW(E222)>$K$1,_xlfn.STDEV.P(OFFSET(E222,0,0,-$K$1)),""),"")
E223: =IF(ISNUMBER(B223),B223/C223,"") | F223: =IF(ISNUMBER(E223),IF(ROW(E223)>$K$1,AVERAGE(OFFSET(E223,0,0,-$K$1)),""),"") | G223: =IF(ISNUMBER(I223),F223+I223*$M$1,"") | H223: =IF(ISNUMBER(I223),F223-I223*$M$1,"") | I223: =IF(ISNUMBER(E223),IF(ROW(E223)>$K$1,_xlfn.STDEV.P(OFFSET(E223,0,0,-$K$1)),""),"")
E224: =IF(ISNUMBER(B224),B224/C224,"") | F224: =IF(ISNUMBER(E224),IF(ROW(E224)>$K$1,AVERAGE(OFFSET(E224,0,0,-$K$1)),""),"") | G224: =IF(ISNUMBER(I224),F224+I224*$M$1,"") | H224: =IF(ISNUMBER(I224),F224-I224*$M$1,"") | I224: =IF(ISNUMBER(E224),IF(ROW(E224)>$K$1,_xlfn.STDEV.P(OFFSET(E224,0,0,-$K$1)),""),"")
E225: =IF(ISNUMBER(B225),B225/C225,"") | F225: =IF(ISNUMBER(E225),IF(ROW(E225)>$K$1,AVERAGE(OFFSET(E225,0,0,-$K$1)),""),"") | G225: =IF(ISNUMBER(I225),F225+I225*$M$1,"") | H225: =IF(ISNUMBER(I225),F225-I225*$M$1,"") | I225: =IF(ISNUMBER(E225),IF(ROW(E225)>$K$1,_xlfn.STDEV.P(OFFSET(E225,0,0,-$K$1)),""),"")
... E2593: =IF(ISNUMBER(B2593),B2593/C2593,"") | F2593: =IF(ISNUMBER(E2593),IF(ROW(E2593)>$K$1,AVERAGE(OFFSET(E2593,0,0,-$K$1)),""),"") | G2593: =IF(ISNUMBER(I2593),F2593+I2593*$M$1,"") | H2593: =IF(ISNUMBER(I2593),F2593-I2593*$M$1,"") | I2593: =IF(ISNUMBER(E2593),IF(ROW(E2593)>$K$1,_xlfn.STDEV.P(OFFSET(E2593,0,0,-$K$1)),""),"")

Sheet Backtest
A1: Data | B1: ITUB4 | C1: BBDC4 | E1: =B1 & "/" & C1 -> ITUB4/BBDC4 | F1: #Desvios | G1: Avg | H1: Desvios | I1: Dias | J1: =Trades!W1 -> 22 | K1: Vender Razao Bater x Desvios | L1: =Trades!Y1 -> 1 | M1: Sair Quando | N1: =Trades!AA1 -> 0 | O1: Comprar Razao Quando | P1: =Trades!AC1 -> -1 | Q1: Sair Quando | R1: =Trades!AE1 -> 0
A2: 40182 | B2: 12.364271 | C2: 9.730924 | E2: =IF(ISNUMBER(B2),B2/C2,"") -> 1.2706163 | F2: =IF(ISNUMBER(G2),(E2-G2)/H2,"") | G2: =IF(ISNUMBER(E2),IF(ROW(E2)>$J$1,AVERAGE(OFFSET(E2,0,0,-$J$1)),""),"") | H2: =IF(ISNUMBER(E2),IF(ROW(E2)>$J$1,_xlfn.STDEV.P(OFFSET(E2,0,0,-$J$1)),""),"")
A3: 40183 | B3: 12.44441 | C3: 9.688052 | E3: =IF(ISNUMBER(B3),B3/C3,"") -> 1.2845111 | F3: =IF(ISNUMBER(G3),(E3-G3)/H3,"") | G3: =IF(ISNUMBER(E3),IF(ROW(E3)>$J$1,AVERAGE(OFFSET(E3,0,0,-$J$1)),""),"") | H3: =IF(ISNUMBER(E3),IF(ROW(E3)>$J$1,_xlfn.STDEV.P(OFFSET(E3,0,0,-$J$1)),""),"")
A4: 40184 | B4: 12.336596 | C4: 9.610507 | E4: =IF(ISNUMBER(B4),B4/C4,"") -> 1.2836571 | F4: =IF(ISNUMBER(G4),(E4-G4)/H4,"") | G4: =IF(ISNUMBER(E4),IF(ROW(E4)>$J$1,AVERAGE(OFFSET(E4,0,0,-$J$1)),""),"") | H4: =IF(ISNUMBER(E4),IF(ROW(E4)>$J$1,_xlfn.STDEV.P(OFFSET(E4,0,0,-$J$1)),""),"")
A5: 40185 | B5: 12.210235 | C5: 9.584696 | E5: =IF(ISNUMBER(B5),B5/C5,"") -> 1.2739303 | F5: =IF(ISNUMBER(G5),(E5-G5)/H5,"") | G5: =IF(ISNUMBER(E5),IF(ROW(E5)>$J$1,AVERAGE(OFFSET(E5,0,0,-$J$1)),""),"") | H5: =IF(ISNUMBER(E5),IF(ROW(E5)>$J$1,_xlfn.STDEV.P(OFFSET(E5,0,0,-$J$1)),""),"") | J5: Venda | K5: Compra | L5: Status | N5: Entrada Long | O5: Saída Long | P5: Entrada Short | Q5: Saída Short
A6: 40186 | B6: 12.025325 | C6: 9.574349 | E6: =IF(ISNUMBER(B6),B6/C6,"") -> 1.255994 | F6: =IF(ISNUMBER(G6),(E6-G6)/H6,"") | G6: =IF(ISNUMBER(E6),IF(ROW(E6)>$J$1,AVERAGE(OFFSET(E6,0,0,-$J$1)),""),"") | H6: =IF(ISNUMBER(E6),IF(ROW(E6)>$J$1,_xlfn.STDEV.P(OFFSET(E6,0,0,-$J$1)),""),"") | J6: =IF(ISNUMBER(F6),IF(AND(J5<>1,F6>$L$1),1,0),"")
A7: 40189 | B7: 11.920492 | C7: 9.582108 | E7: =IF(ISNUMBER(B7),B7/C7,"") -> 1.2440365 | F7: =IF(ISNUMBER(G7),(E7-G7)/H7,"") | G7: =IF(ISNUMBER(E7),IF(ROW(E7)>$J$1,AVERAGE(OFFSET(E7,0,0,-$J$1)),""),"") | H7: =IF(ISNUMBER(E7),IF(ROW(E7)>$J$1,_xlfn.STDEV.P(OFFSET(E7,0,0,-$J$1)),""),"") | J7: =IF(ISNUMBER(F7),IF(AND(J6<>1,F7>$L$1),1,0),"")
A8: 40190 | B8: 11.80956 | C8: 9.610507 | E8: =IF(ISNUMBER(B8),B8/C8,"") -> 1.2288176 | F8: =IF(ISNUMBER(G8),(E8-G8)/H8,"") | G8: =IF(ISNUMBER(E8),IF(ROW(E8)>$J$1,AVERAGE(OFFSET(E8,0,0,-$J$1)),""),"") | H8: =IF(ISNUMBER(E8),IF(ROW(E8)>$J$1,_xlfn.STDEV.P(OFFSET(E8,0,0,-$J$1)),""),"") | J8: =IF(ISNUMBER(F8),IF(AND(J7<>1,F8>$L$1),1,IF(AND(J7=1,F8>$N$1),1,0)),"") | K8: =IF(ISNUMBER(F8),IF(AND(K7<>-1,F8<$P$1),-1,IF(AND(K7=-1,F8<R1),-1,0)),"") | L8: =IF(ISNUMBER(F8),IF(J8=1,1,IF(K8=-1,-1,0)),"") | N8: =IF(AND(L8=1,L7<>1),MAX($N7:N$8)+1,"") | O8: =IF(AND(L8<>1,L7=1),MAX($O7:O$8)+1,"") | P8: =IF(AND(L8=-1,L7<>-1),MAX($P7:P$8)+1,"") | Q8: =IF(AND(L8<>-1,L7=-1),MAX($Q7:Q$8)+1,"")
A9: 40191 | B9: 11.846578 | C9: 9.66218 | E9: =IF(ISNUMBER(B9),B9/C9,"") -> 1.2260771 | F9: =IF(ISNUMBER(G9),(E9-G9)/H9,"") | G9: =IF(ISNUMBER(E9),IF(ROW(E9)>$J$1,AVERAGE(OFFSET(E9,0,0,-$J$1)),""),"") | H9: =IF(ISNUMBER(E9),IF(ROW(E9)>$J$1,_xlfn.STDEV.P(OFFSET(E9,0,0,-$J$1)),""),"") | J9: =IF(ISNUMBER(F9),IF(AND(J8<>1,F9>$L$1),1,IF(AND(J8=1,F9>$N$1),1,0)),"") | K9: =IF(ISNUMBER(F9),IF(AND(K8<>-1,F9<$P$1),-1,IF(AND(K8=-1,F9<R2),-1,0)),"") | L9: =IF(ISNUMBER(F9),IF(J9=1,1,IF(K9=-1,-1,0)),"") | N9: =IF(AND(L9=1,L8<>1),MAX($N$8:N8)+1,"") | O9: =IF(AND(L9<>1,L8=1),MAX($O$8:O8)+1,"") | P9: =IF(AND(L9=-1,L8<>-1),MAX($P$8:P8)+1,"") | Q9: =IF(AND(L9<>-1,L8=-1),MAX($Q$8:Q8)+1,"")
A10: 40192 | B10: 11.683191 | C10: 9.455523 | E10: =IF(ISNUMBER(B10),B10/C10,"") -> 1.2355944 | F10: =IF(ISNUMBER(G10),(E10-G10)/H10,"") | G10: =IF(ISNUMBER(E10),IF(ROW(E10)>$J$1,AVERAGE(OFFSET(E10,0,0,-$J$1)),""),"") | H10: =IF(ISNUMBER(E10),IF(ROW(E10)>$J$1,_xlfn.STDEV.P(OFFSET(E10,0,0,-$J$1)),""),"") | J10: =IF(ISNUMBER(F10),IF(AND(J9<>1,F10>$L$1),1,IF(AND(J9=1,F10>$N$1),1,0)),"") | K10: =IF(ISNUMBER(F10),IF(AND(K9<>-1,F10<$P$1),-1,IF(AND(K9=-1,F10<R3),-1,0)),"") | L10: =IF(ISNUMBER(F10),IF(J10=1,1,IF(K10=-1,-1,0)),"") | N10: =IF(AND(L10=1,L9<>1),MAX($N$8:N9)+1,"") | O10: =IF(AND(L10<>1,L9=1),MAX($O$8:O9)+1,"") | P10: =IF(AND(L10=-1,L9<>-1),MAX($P$8:P9)+1,"") | Q10: =IF(AND(L10<>-1,L9=-1),MAX($Q$8:Q9)+1,"")
A11: 40193 | B11: 11.485968 | C11: 9.321186 | E11: =IF(ISNUMBER(B11),B11/C11,"") -> 1.2322432 | F11: =IF(ISNUMBER(G11),(E11-G11)/H11,"") | G11: =IF(ISNUMBER(E11),IF(ROW(E11)>$J$1,AVERAGE(OFFSET(E11,0,0,-$J$1)),""),"") | H11: =IF(ISNUMBER(E11),IF(ROW(E11)>$J$1,_xlfn.STDEV.P(OFFSET(E11,0,0,-$J$1)),""),"") | J11: =IF(ISNUMBER(F11),IF(AND(J10<>1,F11>$L$1),1,IF(AND(J10=1,F11>$N$1),1,0)),"") | K11: =IF(ISNUMBER(F11),IF(AND(K10<>-1,F11<$P$1),-1,IF(AND(K10=-1,F11<R4),-1,0)),"") | L11: =IF(ISNUMBER(F11),IF(J11=1,1,IF(K11=-1,-1,0)),"") | N11: =IF(AND(L11=1,L10<>1),MAX($N$8:N10)+1,"") | O11: =IF(AND(L11<>1,L10=1),MAX($O$8:O10)+1,"") | P11: =IF(AND(L11=-1,L10<>-1),MAX($P$8:P10)+1,"") | Q11: =IF(AND(L11<>-1,L10=-1),MAX($Q$8:Q10)+1,"")
A12: 40196 | B12: 11.587693 | C12: 9.403846 | E12: =IF(ISNUMBER(B12),B12/C12,"") -> 1.2322291 | F12: =IF(ISNUMBER(G12),(E12-G12)/H12,"") | G12: =IF(ISNUMBER(E12),IF(ROW(E12)>$J$1,AVERAGE(OFFSET(E12,0,0,-$J$1)),""),"") | H12: =IF(ISNUMBER(E12),IF(ROW(E12)>$J$1,_xlfn.STDEV.P(OFFSET(E12,0,0,-$J$1)),""),"") | J12: =IF(ISNUMBER(F12),IF(AND(J11<>1,F12>$L$1),1,IF(AND(J11=1,F12>$N$1),1,0)),"") | K12: =IF(ISNUMBER(F12),IF(AND(K11<>-1,F12<$P$1),-1,IF(AND(K11=-1,F12<R5),-1,0)),"") | L12: =IF(ISNUMBER(F12),IF(J12=1,1,IF(K12=-1,-1,0)),"") | N12: =IF(AND(L12=1,L11<>1),MAX($N$8:N11)+1,"") | O12: =IF(AND(L12<>1,L11=1),MAX($O$8:O11)+1,"") | P12: =IF(AND(L12=-1,L11<>-1),MAX($P$8:P11)+1,"") | Q12: =IF(AND(L12<>-1,L11=-1),MAX($Q$8:Q11)+1,"")
A13: 40197 | B13: 11.556836 | C13: 9.489093 | E13: =IF(ISNUMBER(B13),B13/C13,"") -> 1.2179073 | F13: =IF(ISNUMBER(G13),(E13-G13)/H13,"") | G13: =IF(ISNUMBER(E13),IF(ROW(E13)>$J$1,AVERAGE(OFFSET(E13,0,0,-$J$1)),""),"") | H13: =IF(ISNUMBER(E13),IF(ROW(E13)>$J$1,_xlfn.STDEV.P(OFFSET(E13,0,0,-$J$1)),""),"") | J13: =IF(ISNUMBER(F13),IF(AND(J12<>1,F13>$L$1),1,IF(AND(J12=1,F13>$N$1),1,0)),"") | K13: =IF(ISNUMBER(F13),IF(AND(K12<>-1,F13<$P$1),-1,IF(AND(K12=-1,F13<R6),-1,0)),"") | L13: =IF(ISNUMBER(F13),IF(J13=1,1,IF(K13=-1,-1,0)),"") | N13: =IF(AND(L13=1,L12<>1),MAX($N$8:N12)+1,"") | O13: =IF(AND(L13<>1,L12=1),MAX($O$8:O12)+1,"") | P13: =IF(AND(L13=-1,L12<>-1),MAX($P$8:P12)+1,"") | Q13: =IF(AND(L13<>-1,L12=-1),MAX($Q$8:Q12)+1,"")
A14: 40198 | B14: 11.251733 | C14: 8.422121 | E14: =IF(ISNUMBER(B14),B14/C14,"") -> 1.3359738 | F14: =IF(ISNUMBER(G14),(E14-G14)/H14,"") | G14: =IF(ISNUMBER(E14),IF(ROW(E14)>$J$1,AVERAGE(OFFSET(E14,0,0,-$J$1)),""),"") | H14: =IF(ISNUMBER(E14),IF(ROW(E14)>$J$1,_xlfn.STDEV.P(OFFSET(E14,0,0,-$J$1)),""),"") | J14: =IF(ISNUMBER(F14),IF(AND(J13<>1,F14>$L$1),1,IF(AND(J13=1,F14>$N$1),1,0)),"") | K14: =IF(ISNUMBER(F14),IF(AND(K13<>-1,F14<$P$1),-1,IF(AND(K13=-1,F14<R7),-1,0)),"") | L14: =IF(ISNUMBER(F14),IF(J14=1,1,IF(K14=-1,-1,0)),"") | N14: =IF(AND(L14=1,L13<>1),MAX($N$8:N13)+1,"") | O14: =IF(AND(L14<>1,L13=1),MAX($O$8:O13)+1,"") | P14: =IF(AND(L14=-1,L13<>-1),MAX($P$8:P13)+1,"") | Q14: =IF(AND(L14<>-1,L13=-1),MAX($Q$8:Q13)+1,"")
A15: 40199 | B15: 11.045298 | C15: 8.210292 | E15: =IF(ISNUMBER(B15),B15/C15,"") -> 1.345299 | F15: =IF(ISNUMBER(G15),(E15-G15)/H15,"") | G15: =IF(ISNUMBER(E15),IF(ROW(E15)>$J$1,AVERAGE(OFFSET(E15,0,0,-$J$1)),""),"") | H15: =IF(ISNUMBER(E15),IF(ROW(E15)>$J$1,_xlfn.STDEV.P(OFFSET(E15,0,0,-$J$1)),""),"") | J15: =IF(ISNUMBER(F15),IF(AND(J14<>1,F15>$L$1),1,IF(AND(J14=1,F15>$N$1),1,0)),"") | K15: =IF(ISNUMBER(F15),IF(AND(K14<>-1,F15<$P$1),-1,IF(AND(K14=-1,F15<R8),-1,0)),"") | L15: =IF(ISNUMBER(F15),IF(J15=1,1,IF(K15=-1,-1,0)),"") | N15: =IF(AND(L15=1,L14<>1),MAX($N$8:N14)+1,"") | O15: =IF(AND(L15<>1,L14=1),MAX($O$8:O14)+1,"") | P15: =IF(AND(L15=-1,L14<>-1),MAX($P$8:P14)+1,"") | Q15: =IF(AND(L15<>-1,L14=-1),MAX($Q$8:Q14)+1,"")
A16: 40200 | B16: 11.171656 | C16: 8.210292 | E16: =IF(ISNUMBER(B16),B16/C16,"") -> 1.3606892 | F16: =IF(ISNUMBER(G16),(E16-G16)/H16,"") | G16: =IF(ISNUMBER(E16),IF(ROW(E16)>$J$1,AVERAGE(OFFSET(E16,0,0,-$J$1)),""),"") | H16: =IF(ISNUMBER(E16),IF(ROW(E16)>$J$1,_xlfn.STDEV.P(OFFSET(E16,0,0,-$J$1)),""),"") | J16: =IF(ISNUMBER(F16),IF(AND(J15<>1,F16>$L$1),1,IF(AND(J15=1,F16>$N$1),1,0)),"") | K16: =IF(ISNUMBER(F16),IF(AND(K15<>-1,F16<$P$1),-1,IF(AND(K15=-1,F16<R9),-1,0)),"") | L16: =IF(ISNUMBER(F16),IF(J16=1,1,IF(K16=-1,-1,0)),"") | N16: =IF(AND(L16=1,L15<>1),MAX($N$8:N15)+1,"") | O16: =IF(AND(L16<>1,L15=1),MAX($O$8:O15)+1,"") | P16: =IF(AND(L16=-1,L15<>-1),MAX($P$8:P15)+1,"") | Q16: =IF(AND(L16<>-1,L15=-1),MAX($Q$8:Q15)+1,"")
A17: 40204 | B17: 11.199345 | C17: 8.251617 | E17: =IF(ISNUMBER(B17),B17/C17,"") -> 1.3572303 | F17: =IF(ISNUMBER(G17),(E17-G17)/H17,"") | G17: =IF(ISNUMBER(E17),IF(ROW(E17)>$J$1,AVERAGE(OFFSET(E17,0,0,-$J$1)),""),"") | H17: =IF(ISNUMBER(E17),IF(ROW(E17)>$J$1,_xlfn.STDEV.P(OFFSET(E17,0,0,-$J$1)),""),"") | J17: =IF(ISNUMBER(F17),IF(AND(J16<>1,F17>$L$1),1,IF(AND(J16=1,F17>$N$1),1,0)),"") | K17: =IF(ISNUMBER(F17),IF(AND(K16<>-1,F17<$P$1),-1,IF(AND(K16=-1,F17<R10),-1,0)),"") | L17: =IF(ISNUMBER(F17),IF(J17=1,1,IF(K17=-1,-1,0)),"") | N17: =IF(AND(L17=1,L16<>1),MAX($N$8:N16)+1,"") | O17: =IF(AND(L17<>1,L16=1),MAX($O$8:O16)+1,"") | P17: =IF(AND(L17=-1,L16<>-1),MAX($P$8:P16)+1,"") | Q17: =IF(AND(L17<>-1,L16=-1),MAX($Q$8:Q16)+1,"")
A18: 40205 | B18: 11.039138 | C18: 8.068181 | E18: =IF(ISNUMBER(B18),B18/C18,"") -> 1.3682313 | F18: =IF(ISNUMBER(G18),(E18-G18)/H18,"") | G18: =IF(ISNUMBER(E18),IF(ROW(E18)>$J$1,AVERAGE(OFFSET(E18,0,0,-$J$1)),""),"") | H18: =IF(ISNUMBER(E18),IF(ROW(E18)>$J$1,_xlfn.STDEV.P(OFFSET(E18,0,0,-$J$1)),""),"") | J18: =IF(ISNUMBER(F18),IF(AND(J17<>1,F18>$L$1),1,IF(AND(J17=1,F18>$N$1),1,0)),"") | K18: =IF(ISNUMBER(F18),IF(AND(K17<>-1,F18<$P$1),-1,IF(AND(K17=-1,F18<R11),-1,0)),"") | L18: =IF(ISNUMBER(F18),IF(J18=1,1,IF(K18=-1,-1,0)),"") | N18: =IF(AND(L18=1,L17<>1),MAX($N$8:N17)+1,"") | O18: =IF(AND(L18<>1,L17=1),MAX($O$8:O17)+1,"") | P18: =IF(AND(L18=-1,L17<>-1),MAX($P$8:P17)+1,"") | Q18: =IF(AND(L18<>-1,L17=-1),MAX($Q$8:Q17)+1,"")
A19: 40206 | B19: 11.368882 | C19: 8.205113 | E19: =IF(ISNUMBER(B19),B19/C19,"") -> 1.3855851 | F19: =IF(ISNUMBER(G19),(E19-G19)/H19,"") | G19: =IF(ISNUMBER(E19),IF(ROW(E19)>$J$1,AVERAGE(OFFSET(E19,0,0,-$J$1)),""),"") | H19: =IF(ISNUMBER(E19),IF(ROW(E19)>$J$1,_xlfn.STDEV.P(OFFSET(E19,0,0,-$J$1)),""),"") | J19: =IF(ISNUMBER(F19),IF(AND(J18<>1,F19>$L$1),1,IF(AND(J18=1,F19>$N$1),1,0)),"") | K19: =IF(ISNUMBER(F19),IF(AND(K18<>-1,F19<$P$1),-1,IF(AND(K18=-1,F19<R12),-1,0)),"") | L19: =IF(ISNUMBER(F19),IF(J19=1,1,IF(K19=-1,-1,0)),"") | N19: =IF(AND(L19=1,L18<>1),MAX($N$8:N18)+1,"") | O19: =IF(AND(L19<>1,L18=1),MAX($O$8:O18)+1,"") | P19: =IF(AND(L19=-1,L18<>-1),MAX($P$8:P18)+1,"") | Q19: =IF(AND(L19<>-1,L18=-1),MAX($Q$8:Q18)+1,"")
A20: 40207 | B20: 11.134632 | C20: 8.094053 | E20: =IF(ISNUMBER(B20),B20/C20,"") -> 1.3756559 | F20: =IF(ISNUMBER(G20),(E20-G20)/H20,"") | G20: =IF(ISNUMBER(E20),IF(ROW(E20)>$J$1,AVERAGE(OFFSET(E20,0,0,-$J$1)),""),"") | H20: =IF(ISNUMBER(E20),IF(ROW(E20)>$J$1,_xlfn.STDEV.P(OFFSET(E20,0,0,-$J$1)),""),"") | J20: =IF(ISNUMBER(F20),IF(AND(J19<>1,F20>$L$1),1,IF(AND(J19=1,F20>$N$1),1,0)),"") | K20: =IF(ISNUMBER(F20),IF(AND(K19<>-1,F20<$P$1),-1,IF(AND(K19=-1,F20<R13),-1,0)),"") | L20: =IF(ISNUMBER(F20),IF(J20=1,1,IF(K20=-1,-1,0)),"") | N20: =IF(AND(L20=1,L19<>1),MAX($N$8:N19)+1,"") | O20: =IF(AND(L20<>1,L19=1),MAX($O$8:O19)+1,"") | P20: =IF(AND(L20=-1,L19<>-1),MAX($P$8:P19)+1,"") | Q20: =IF(AND(L20<>-1,L19=-1),MAX($Q$8:Q19)+1,"")
... A2593: 44008 | B2593: 25.6 | C2593: 20.690001 | E2593: =IF(ISNUMBER(B2593),B2593/C2593,"") -> 1.2373127 | F2593: =IF(ISNUMBER(G2593),(E2593-G2593)/H2593,"") -> 0.90235476 | G2593: =IF(ISNUMBER(E2593),IF(ROW(E2593)>$J$1,AVERAGE(OFFSET(E2593,0,0,-$J$1)),""),"") -> 1.2194161 | H2593: =IF(ISNUMBER(E2593),IF(ROW(E2593)>$J$1,_xlfn.STDEV.P(OFFSET(E2593,0,0,-$J$1)),""),"") -> 0.019833133 | J2593: =IF(ISNUMBER(F2593),IF(AND(J2592<>1,F2593>$L$1),1,IF(AND(J2592=1,F2593>$N$1),1,0)),"") -> 1 | K2593: =IF(ISNUMBER(F2593),IF(AND(K2592<>-1,F2593<$P$1),-1,IF(AND(K2592=-1,F2593<R2586),-1,0)),"") -> 0 | L2593: =IF(ISNUMBER(F2593),IF(J2593=1,1,IF(K2593=-1,-1,0)),"") -> 1 | N2593: =IF(AND(L2593=1,L2592<>1),MAX($N$8:N2592)+1,"") | O2593: =IF(AND(L2593<>1,L2592=1),MAX($O$8:O2592)+1,"") | P2593: =IF(AND(L2593=-1,L2592<>-1),MAX($P$8:P2592)+1,"") | Q2593: =IF(AND(L2593<>-1,L2592=-1),MAX($Q$8:Q2592)+1,"")

Sheet Trades
A1: Tamanho | B1: =100000 -> 100000 | D1: Venda Razão | O1: Compra Razão | V1: Dias | W1: 22 | X1: Vender Razao Bater x Desvios | Y1: 1 | Z1: Sair Quando | AA1: 0 | AB1: Comprar Razao Quando | AC1: -1 | AD1: Sair Quando | AE1: 0
B2: Início | C2: Fim | D2: Compra | E2: %Chg | F2: Vende | G2: %Chg | H2: LS | I2: P&L | J2: #Dias | M2: Início | N2: Fim | O2: Compra | P2: %Chg | Q2: Vende | R2: %Chg | S2: LS | T2: P&L | U2: #Dias
A3: 1 | B3: =IFERROR(INDEX(Backtest!$A$8:$A$5000,MATCH(A3,Backtest!$N$8:$N$5000,0)),"") -> 40212 | C3: =IFERROR(INDEX(Backtest!$A$8:$A$5000,MATCH(A3,Backtest!$O$8:$O$5000,0)),"") -> 40233 | D3: =IF(ISNUMBER(B3),Backtest!$C$1,"") -> BBDC4 | E3: =IFERROR(VLOOKUP(C3,Backtest!A:C,3,FALSE)/VLOOKUP(B3,Backtest!A:C,3,FALSE)-1,"") -> 0.39554407 | F3: =IF(ISNUMBER(C3),Backtest!$B$1,"") -> ITUB4 | G3: =IFERROR(VLOOKUP(C3,Backtest!A:C,2,FALSE)/VLOOKUP(B3,Backtest!A:C,2,FALSE)-1,"") -> -0.041196921 | H3: =IF(ISNUMBER(C3),E3-G3,"") -> 0.43674099 | I3: =IF(ISNUMBER(C3),H3*$B$1,"") -> 43674.099 | J3: =IF(ISNUMBER(C3),NETWORKDAYS(B3,C3),"") -> 16 | L3: 1 | M3: =IFERROR(INDEX(Backtest!$A$8:$A$5000,MATCH(L3,Backtest!$P$8:$P$5000,0)),"") -> 40233 | N3: =IFERROR(INDEX(Backtest!$A$8:$A$5000,MATCH(L3,Backtest!$Q$8:$Q$5000,0)),"") -> 40262 | O3: =IF(ISNUMBER(M3),Backtest!$B$1,"") -> ITUB4 | P3: =IFERROR(VLOOKUP(N3,Backtest!A:C,2,FALSE)/VLOOKUP(M3,Backtest!A:C,2,FALSE)-1,"") -> 0.037348757 | Q3: =IF(ISNUMBER(N3),Backtest!$C$1,"") -> BBDC4 | R3: =IFERROR(VLOOKUP(N3,Backtest!A:C,3,FALSE)/VLOOKUP(M3,Backtest!A:C,3,FALSE)-1,"") -> 0.010781345 | S3: =IF(ISNUMBER(N3),P3-R3,"") -> 0.026567411 | T3: =IF(ISNUMBER(N3),S3*$B$1,"") -> 2656.7411 | U3: =IF(ISNUMBER(N3),NETWORKDAYS(M3,N3),"") -> 22
A4: 2 | B4: =IFERROR(INDEX(Backtest!$A$8:$A$5000,MATCH(A4,Backtest!$N$8:$N$5000,0)),"") -> 40263 | C4: =IFERROR(INDEX(Backtest!$A$8:$A$5000,MATCH(A4,Backtest!$O$8:$O$5000,0)),"") -> 40269 | D4: =IF(ISNUMBER(B4),Backtest!$C$1,"") -> BBDC4 | E4: =IFERROR(VLOOKUP(C4,Backtest!A:C,3,FALSE)/VLOOKUP(B4,Backtest!A:C,3,FALSE)-1,"") -> 0.05668487 | F4: =IF(ISNUMBER(C4),Backtest!$B$1,"") -> ITUB4 | G4: =IFERROR(VLOOKUP(C4,Backtest!A:C,2,FALSE)/VLOOKUP(B4,Backtest!A:C,2,FALSE)-1,"") -> 0.042551006 | H4: =IF(ISNUMBER(C4),E4-G4,"") -> 0.014133863 | I4: =IF(ISNUMBER(C4),H4*$B$1,"") -> 1413.3863 | J4: =IF(ISNUMBER(C4),NETWORKDAYS(B4,C4),"") -> 5 | L4: 2 | M4: =IFERROR(INDEX(Backtest!$A$8:$A$5000,MATCH(L4,Backtest!$P$8:$P$5000,0)),"") -> 40275 | N4: =IFERROR(INDEX(Backtest!$A$8:$A$5000,MATCH(L4,Backtest!$Q$8:$Q$5000,0)),"") -> 40277 | O4: =IF(ISNUMBER(M4),Backtest!$B$1,"") -> ITUB4 | P4: =IFERROR(VLOOKUP(N4,Backtest!A:C,2,FALSE)/VLOOKUP(M4,Backtest!A:C,2,FALSE)-1,"") -> 0.038859942 | Q4: =IF(ISNUMBER(N4),Backtest!$C$1,"") -> BBDC4 | R4: =IFERROR(VLOOKUP(N4,Backtest!A:C,3,FALSE)/VLOOKUP(M4,Backtest!A:C,3,FALSE)-1,"") -> 0.029902665 | S4: =IF(ISNUMBER(N4),P4-R4,"") -> 0.0089572771 | T4: =IF(ISNUMBER(N4),S4*$B$1,"") -> 895.72771 | U4: =IF(ISNUMBER(N4),NETWORKDAYS(M4,N4),"") -> 3 | W4: Início | X4: =MIN(Backtest!A:A) -> 40182
A5: 3 | B5: =IFERROR(INDEX(Backtest!$A$8:$A$5000,MATCH(A5,Backtest!$N$8:$N$5000,0)),"") -> 40281 | C5: =IFERROR(INDEX(Backtest!$A$8:$A$5000,MATCH(A5,Backtest!$O$8:$O$5000,0)),"") -> 40290 | D5: =IF(ISNUMBER(B5),Backtest!$C$1,"") -> BBDC4 | E5: =IFERROR(VLOOKUP(C5,Backtest!A:C,3,FALSE)/VLOOKUP(B5,Backtest!A:C,3,FALSE)-1,"") -> -0.033335428 | F5: =IF(ISNUMBER(C5),Backtest!$B$1,"") -> ITUB4 | G5: =IFERROR(VLOOKUP(C5,Backtest!A:C,2,FALSE)/VLOOKUP(B5,Backtest!A:C,2,FALSE)-1,"") -> -0.038799021 | H5: =IF(ISNUMBER(C5),E5-G5,"") -> 0.0054635927 | I5: =IF(ISNUMBER(C5),H5*$B$1,"") -> 546.35927 | J5: =IF(ISNUMBER(C5),NETWORKDAYS(B5,C5),"") -> 8 | L5: 3 | M5: =IFERROR(INDEX(Backtest!$A$8:$A$5000,MATCH(L5,Backtest!$P$8:$P$5000,0)),"") -> 40295 | N5: =IFERROR(INDEX(Backtest!$A$8:$A$5000,MATCH(L5,Backtest!$Q$8:$Q$5000,0)),"") -> 40301 | O5: =IF(ISNUMBER(M5),Backtest!$B$1,"") -> ITUB4 | P5: =IFERROR(VLOOKUP(N5,Backtest!A:C,2,FALSE)/VLOOKUP(M5,Backtest!A:C,2,FALSE)-1,"") -> 0.044641162 | Q5: =IF(ISNUMBER(N5),Backtest!$C$1,"") -> BBDC4 | R5: =IFERROR(VLOOKUP(N5,Backtest!A:C,3,FALSE)/VLOOKUP(M5,Backtest!A:C,3,FALSE)-1,"") -> 0.030240673 | S5: =IF(ISNUMBER(N5),P5-R5,"") -> 0.014400488 | T5: =IF(ISNUMBER(N5),S5*$B$1,"") -> 1440.0488 | U5: =IF(ISNUMBER(N5),NETWORKDAYS(M5,N5),"") -> 5 | W5: Fim | X5: =MAX(Backtest!A:A) -> 44008
A6: 4 | B6: =IFERROR(INDEX(Backtest!$A$8:$A$5000,MATCH(A6,Backtest!$N$8:$N$5000,0)),"") -> 40347 | C6: =IFERROR(INDEX(Backtest!$A$8:$A$5000,MATCH(A6,Backtest!$O$8:$O$5000,0)),"") -> 40353 | D6: =IF(ISNUMBER(B6),Backtest!$C$1,"") -> BBDC4 | E6: =IFERROR(VLOOKUP(C6,Backtest!A:C,3,FALSE)/VLOOKUP(B6,Backtest!A:C,3,FALSE)-1,"") -> 0 | F6: =IF(ISNUMBER(C6),Backtest!$B$1,"") -> ITUB4 | G6: =IFERROR(VLOOKUP(C6,Backtest!A:C,2,FALSE)/VLOOKUP(B6,Backtest!A:C,2,FALSE)-1,"") -> -0.026913868 | H6: =IF(ISNUMBER(C6),E6-G6,"") -> 0.026913868 | I6: =IF(ISNUMBER(C6),H6*$B$1,"") -> 2691.3868 | J6: =IF(ISNUMBER(C6),NETWORKDAYS(B6,C6),"") -> 5 | L6: 4 | M6: =IFERROR(INDEX(Backtest!$A$8:$A$5000,MATCH(L6,Backtest!$P$8:$P$5000,0)),"") -> 40304 | N6: =IFERROR(INDEX(Backtest!$A$8:$A$5000,MATCH(L6,Backtest!$Q$8:$Q$5000,0)),"") -> 40308 | O6: =IF(ISNUMBER(M6),Backtest!$B$1,"") -> ITUB4 | P6: =IFERROR(VLOOKUP(N6,Backtest!A:C,2,FALSE)/VLOOKUP(M6,Backtest!A:C,2,FALSE)-1,"") -> 0.040008568 | Q6: =IF(ISNUMBER(N6),Backtest!$C$1,"") -> BBDC4 | R6: =IFERROR(VLOOKUP(N6,Backtest!A:C,3,FALSE)/VLOOKUP(M6,Backtest!A:C,3,FALSE)-1,"") -> 0.021293894 | S6: =IF(ISNUMBER(N6),P6-R6,"") -> 0.018714674 | T6: =IF(ISNUMBER(N6),S6*$B$1,"") -> 1871.4674 | U6: =IF(ISNUMBER(N6),NETWORKDAYS(M6,N6),"") -> 3 | W6: Numero Trades | X6: =COUNTIFS(N3:N102,">0")+COUNTIFS(C3:C102,">0") -> 177
A7: 5 | B7: =IFERROR(INDEX(Backtest!$A$8:$A$5000,MATCH(A7,Backtest!$N$8:$N$5000,0)),"") -> 40371 | C7: =IFERROR(INDEX(Backtest!$A$8:$A$5000,MATCH(A7,Backtest!$O$8:$O$5000,0)),"") -> 40399 | D7: =IF(ISNUMBER(B7),Backtest!$C$1,"") -> BBDC4 | E7: =IFERROR(VLOOKUP(C7,Backtest!A:C,3,FALSE)/VLOOKUP(B7,Backtest!A:C,3,FALSE)-1,"") -> 0.0026126721 | F7: =IF(ISNUMBER(C7),Backtest!$B$1,"") -> ITUB4 | G7: =IFERROR(VLOOKUP(C7,Backtest!A:C,2,FALSE)/VLOOKUP(B7,Backtest!A:C,2,FALSE)-1,"") -> 0.034802115 | H7: =IF(ISNUMBER(C7),E7-G7,"") -> -0.032189443 | I7: =IF(ISNUMBER(C7),H7*$B$1,"") -> -3218.9443 | J7: =IF(ISNUMBER(C7),NETWORKDAYS(B7,C7),"") -> 21 | L7: 5 | M7: =IFERROR(INDEX(Backtest!$A$8:$A$5000,MATCH(L7,Backtest!$P$8:$P$5000,0)),"") -> 40310 | N7: =IFERROR(INDEX(Backtest!$A$8:$A$5000,MATCH(L7,Backtest!$Q$8:$Q$5000,0)),"") -> 40339 | O7: =IF(ISNUMBER(M7),Backtest!$B$1,"") -> ITUB4 | P7: =IFERROR(VLOOKUP(N7,Backtest!A:C,2,FALSE)/VLOOKUP(M7,Backtest!A:C,2,FALSE)-1,"") -> -0.072069485 | Q7: =IF(ISNUMBER(N7),Backtest!$C$1,"") -> BBDC4 | R7: =IFERROR(VLOOKUP(N7,Backtest!A:C,3,FALSE)/VLOOKUP(M7,Backtest!A:C,3,FALSE)-1,"") -> -0.057024904 | S7: =IF(ISNUMBER(N7),P7-R7,"") -> -0.015044582 | T7: =IF(ISNUMBER(N7),S7*$B$1,"") -> -1504.4582 | U7: =IF(ISNUMBER(N7),NETWORKDAYS(M7,N7),"") -> 22 | W7: %Acertos | X7: =(COUNTIFS(S3:S102,">0")+COUNTIFS(H3:H102,">0"))/X6 -> 0.75706215
A8: 6 | B8: =IFERROR(INDEX(Backtest!$A$8:$A$5000,MATCH(A8,Backtest!$N$8:$N$5000,0)),"") -> 40415 | C8: =IFERROR(INDEX(Backtest!$A$8:$A$5000,MATCH(A8,Backtest!$O$8:$O$5000,0)),"") -> 40430 | D8: =IF(ISNUMBER(B8),Backtest!$C$1,"") -> BBDC4 | E8: =IFERROR(VLOOKUP(C8,Backtest!A:C,3,FALSE)/VLOOKUP(B8,Backtest!A:C,3,FALSE)-1,"") -> 0.033797334 | F8: =IF(ISNUMBER(C8),Backtest!$B$1,"") -> ITUB4 | G8: =IFERROR(VLOOKUP(C8,Backtest!A:C,2,FALSE)/VLOOKUP(B8,Backtest!A:C,2,FALSE)-1,"") -> 0.019017325 | H8: =IF(ISNUMBER(C8),E8-G8,"") -> 0.014780008 | I8: =IF(ISNUMBER(C8),H8*$B$1,"") -> 1478.0008 | J8: =IF(ISNUMBER(C8),NETWORKDAYS(B8,C8),"") -> 12 | L8: 6 | M8: =IFERROR(INDEX(Backtest!$A$8:$A$5000,MATCH(L8,Backtest!$P$8:$P$5000,0)),"") -> 40353 | N8: =IFERROR(INDEX(Backtest!$A$8:$A$5000,MATCH(L8,Backtest!$Q$8:$Q$5000,0)),"") -> 40357 | O8: =IF(ISNUMBER(M8),Backtest!$B$1,"") -> ITUB4 | P8: =IFERROR(VLOOKUP(N8,Backtest!A:C,2,FALSE)/VLOOKUP(M8,Backtest!A:C,2,FALSE)-1,"") -> 0.0046609288 | Q8: =IF(ISNUMBER(N8),Backtest!$C$1,"") -> BBDC4 | R8: =IFERROR(VLOOKUP(N8,Backtest!A:C,3,FALSE)/VLOOKUP(M8,Backtest!A:C,3,FALSE)-1,"") -> -0.014489869 | S8: =IF(ISNUMBER(N8),P8-R8,"") -> 0.019150798 | T8: =IF(ISNUMBER(N8),S8*$B$1,"") -> 1915.0798 | U8: =IF(ISNUMBER(N8),NETWORKDAYS(M8,N8),"") -> 3 | W8: Avg Win | X8: =AVERAGE(H3:H102,S3:S102) -> 0.014501451
A9: 7 | B9: =IFERROR(INDEX(Backtest!$A$8:$A$5000,MATCH(A9,Backtest!$N$8:$N$5000,0)),"") -> 40441 | C9: =IFERROR(INDEX(Backtest!$A$8:$A$5000,MATCH(A9,Backtest!$O$8:$O$5000,0)),"") -> 40442 | D9: =IF(ISNUMBER(B9),Backtest!$C$1,"") -> BBDC4 | E9: =IFERROR(VLOOKUP(C9,Backtest!A:C,3,FALSE)/VLOOKUP(B9,Backtest!A:C,3,FALSE)-1,"") -> 0.14653215 | F9: =IF(ISNUMBER(C9),Backtest!$B$1,"") -> ITUB4 | G9: =IFERROR(VLOOKUP(C9,Backtest!A:C,2,FALSE)/VLOOKUP(B9,Backtest!A:C,2,FALSE)-1,"") -> -0.015643034 | H9: =IF(ISNUMBER(C9),E9-G9,"") -> 0.16217519 | I9: =IF(ISNUMBER(C9),H9*$B$1,"") -> 16217.519 | J9: =IF(ISNUMBER(C9),NETWORKDAYS(B9,C9),"") -> 2 | L9: 7 | M9: =IFERROR(INDEX(Backtest!$A$8:$A$5000,MATCH(L9,Backtest!$P$8:$P$5000,0)),"") -> 40364 | N9: =IFERROR(INDEX(Backtest!$A$8:$A$5000,MATCH(L9,Backtest!$Q$8:$Q$5000,0)),"") -> 40371 | O9: =IF(ISNUMBER(M9),Backtest!$B$1,"") -> ITUB4 | P9: =IFERROR(VLOOKUP(N9,Backtest!A:C,2,FALSE)/VLOOKUP(M9,Backtest!A:C,2,FALSE)-1,"") -> 0.11200469 | Q9: =IF(ISNUMBER(N9),Backtest!$C$1,"") -> BBDC4 | R9: =IFERROR(VLOOKUP(N9,Backtest!A:C,3,FALSE)/VLOOKUP(M9,Backtest!A:C,3,FALSE)-1,"") -> -0.24540042 | S9: =IF(ISNUMBER(N9),P9-R9,"") -> 0.35740511 | T9: =IF(ISNUMBER(N9),S9*$B$1,"") -> 35740.511 | U9: =IF(ISNUMBER(N9),NETWORKDAYS(M9,N9),"") -> 6 | W9: Avg Position | X9: =AVERAGE(J3:J102,U3:U102) -> 12.632768
A10: 8 | B10: =IFERROR(INDEX(Backtest!$A$8:$A$5000,MATCH(A10,Backtest!$N$8:$N$5000,0)),"") -> 40504 | C10: =IFERROR(INDEX(Backtest!$A$8:$A$5000,MATCH(A10,Backtest!$O$8:$O$5000,0)),"") -> 40506 | D10: =IF(ISNUMBER(B10),Backtest!$C$1,"") -> BBDC4 | E10: =IFERROR(VLOOKUP(C10,Backtest!A:C,3,FALSE)/VLOOKUP(B10,Backtest!A:C,3,FALSE)-1,"") -> 0.0028915949 | F10: =IF(ISNUMBER(C10),Backtest!$B$1,"") -> ITUB4 | G10: =IFERROR(VLOOKUP(C10,Backtest!A:C,2,FALSE)/VLOOKUP(B10,Backtest!A:C,2,FALSE)-1,"") -> -0.017922639 | H10: =IF(ISNUMBER(C10),E10-G10,"") -> 0.020814234 | I10: =IF(ISNUMBER(C10),H10*$B$1,"") -> 2081.4234 | J10: =IF(ISNUMBER(C10),NETWORKDAYS(B10,C10),"") -> 3 | L10: 8 | M10: =IFERROR(INDEX(Backtest!$A$8:$A$5000,MATCH(L10,Backtest!$P$8:$P$5000,0)),"") -> 40434 | N10: =IFERROR(INDEX(Backtest!$A$8:$A$5000,MATCH(L10,Backtest!$Q$8:$Q$5000,0)),"") -> 40441 | O10: =IF(ISNUMBER(M10),Backtest!$B$1,"") -> ITUB4 | P10: =IFERROR(VLOOKUP(N10,Backtest!A:C,2,FALSE)/VLOOKUP(M10,Backtest!A:C,2,FALSE)-1,"") -> 0.012988412 | Q10: =IF(ISNUMBER(N10),Backtest!$C$1,"") -> BBDC4 | R10: =IFERROR(VLOOKUP(N10,Backtest!A:C,3,FALSE)/VLOOKUP(M10,Backtest!A:C,3,FALSE)-1,"") -> -0.12834872 | S10: =IF(ISNUMBER(N10),P10-R10,"") -> 0.14133713 | T10: =IF(ISNUMBER(N10),S10*$B$1,"") -> 14133.713 | U10: =IF(ISNUMBER(N10),NETWORKDAYS(M10,N10),"") -> 6 | W10: P&L | X10: =SUM(I3:I102)+SUM(T3:T102) -> 256675.68
A11: 9 | B11: =IFERROR(INDEX(Backtest!$A$8:$A$5000,MATCH(A11,Backtest!$N$8:$N$5000,0)),"") -> 40541 | C11: =IFERROR(INDEX(Backtest!$A$8:$A$5000,MATCH(A11,Backtest!$O$8:$O$5000,0)),"") -> 40548 | D11: =IF(ISNUMBER(B11),Backtest!$C$1,"") -> BBDC4 | E11: =IFERROR(VLOOKUP(C11,Backtest!A:C,3,FALSE)/VLOOKUP(B11,Backtest!A:C,3,FALSE)-1,"") -> 0.046330358 | F11: =IF(ISNUMBER(C11),Backtest!$B$1,"") -> ITUB4 | G11: =IFERROR(VLOOKUP(C11,Backtest!A:C,2,FALSE)/VLOOKUP(B11,Backtest!A:C,2,FALSE)-1,"") -> 0.028787646 | H11: =IF(ISNUMBER(C11),E11-G11,"") -> 0.017542712 | I11: =IF(ISNUMBER(C11),H11*$B$1,"") -> 1754.2712 | J11: =IF(ISNUMBER(C11),NETWORKDAYS(B11,C11),"") -> 6 | L11: 9 | M11: =IFERROR(INDEX(Backtest!$A$8:$A$5000,MATCH(L11,Backtest!$P$8:$P$5000,0)),"") -> 40476 | N11: =IFERROR(INDEX(Backtest!$A$8:$A$5000,MATCH(L11,Backtest!$Q$8:$Q$5000,0)),"") -> 40493 | O11: =IF(ISNUMBER(M11),Backtest!$B$1,"") -> ITUB4 | P11: =IFERROR(VLOOKUP(N11,Backtest!A:C,2,FALSE)/VLOOKUP(M11,Backtest!A:C,2,FALSE)-1,"") -> -0.011138189 | Q11: =IF(ISNUMBER(N11),Backtest!$C$1,"") -> BBDC4 | R11: =IFERROR(VLOOKUP(N11,Backtest!A:C,3,FALSE)/VLOOKUP(M11,Backtest!A:C,3,FALSE)-1,"") -> -0.015373386 | S11: =IF(ISNUMBER(N11),P11-R11,"") -> 0.0042351968 | T11: =IF(ISNUMBER(N11),S11*$B$1,"") -> 423.51968 | U11: =IF(ISNUMBER(N11),NETWORKDAYS(M11,N11),"") -> 14
A12: 10 | B12: =IFERROR(INDEX(Backtest!$A$8:$A$5000,MATCH(A12,Backtest!$N$8:$N$5000,0)),"") -> 40556 | C12: =IFERROR(INDEX(Backtest!$A$8:$A$5000,MATCH(A12,Backtest!$O$8:$O$5000,0)),"") -> 40557 | D12: =IF(ISNUMBER(B12),Backtest!$C$1,"") -> BBDC4 | E12: =IFERROR(VLOOKUP(C12,Backtest!A:C,3,FALSE)/VLOOKUP(B12,Backtest!A:C,3,FALSE)-1,"") -> 0.009410682 | F12: =IF(ISNUMBER(C12),Backtest!$B$1,"") -> ITUB4 | G12: =IFERROR(VLOOKUP(C12,Backtest!A:C,2,FALSE)/VLOOKUP(B12,Backtest!A:C,2,FALSE)-1,"") -> -0.011233039 | H12: =IF(ISNUMBER(C12),E12-G12,"") -> 0.020643721 | I12: =IF(ISNUMBER(C12),H12*$B$1,"") -> 2064.3721 | J12: =IF(ISNUMBER(C12),NETWORKDAYS(B12,C12),"") -> 2 | L12: 10 | M12: =IFERROR(INDEX(Backtest!$A$8:$A$5000,MATCH(L12,Backtest!$P$8:$P$5000,0)),"") -> 40511 | N12: =IFERROR(INDEX(Backtest!$A$8:$A$5000,MATCH(L12,Backtest!$Q$8:$Q$5000,0)),"") -> 40534 | O12: =IF(ISNUMBER(M12),Backtest!$B$1,"") -> ITUB4 | P12: =IFERROR(VLOOKUP(N12,Backtest!A:C,2,FALSE)/VLOOKUP(M12,Backtest!A:C,2,FALSE)-1,"") -> -0.0036286813 | Q12: =IF(ISNUMBER(N12),Backtest!$C$1,"") -> BBDC4 | R12: =IFERROR(VLOOKUP(N12,Backtest!A:C,3,FALSE)/VLOOKUP(M12,Backtest!A:C,3,FALSE)-1,"") -> -0.0016814909 | S12: =IF(ISNUMBER(N12),P12-R12,"") -> -0.0019471903 | T12: =IF(ISNUMBER(N12),S12*$B$1,"") -> -194.71903 | U12: =IF(ISNUMBER(N12),NETWORKDAYS(M12,N12),"") -> 18
A13: 11 | B13: =IFERROR(INDEX(Backtest!$A$8:$A$5000,MATCH(A13,Backtest!$N$8:$N$5000,0)),"") -> 40585 | C13: =IFERROR(INDEX(Backtest!$A$8:$A$5000,MATCH(A13,Backtest!$O$8:$O$5000,0)),"") -> 40611 | D13: =IF(ISNUMBER(B13),Backtest!$C$1,"") -> BBDC4 | E13: =IFERROR(VLOOKUP(C13,Backtest!A:C,3,FALSE)/VLOOKUP(B13,Backtest!A:C,3,FALSE)-1,"") -> 0 | F13: =IF(ISNUMBER(C13),Backtest!$B$1,"") -> ITUB4 | G13: =IFERROR(VLOOKUP(C13,Backtest!A:C,2,FALSE)/VLOOKUP(B13,Backtest!A:C,2,FALSE)-1,"") -> 0.0034821214 | H13: =IF(ISNUMBER(C13),E13-G13,"") -> -0.0034821214 | I13: =IF(ISNUMBER(C13),H13*$B$1,"") -> -348.21214 | J13: =IF(ISNUMBER(C13),NETWORKDAYS(B13,C13),"") -> 19 | L13: 11 | M13: =IFERROR(INDEX(Backtest!$A$8:$A$5000,MATCH(L13,Backtest!$P$8:$P$5000,0)),"") -> 40560 | N13: =IFERROR(INDEX(Backtest!$A$8:$A$5000,MATCH(L13,Backtest!$Q$8:$Q$5000,0)),"") -> 40582 | O13: =IF(ISNUMBER(M13),Backtest!$B$1,"") -> ITUB4 | P13: =IFERROR(VLOOKUP(N13,Backtest!A:C,2,FALSE)/VLOOKUP(M13,Backtest!A:C,2,FALSE)-1,"") -> -0.082543846 | Q13: =IF(ISNUMBER(N13),Backtest!$C$1,"") -> BBDC4 | R13: =IFERROR(VLOOKUP(N13,Backtest!A:C,3,FALSE)/VLOOKUP(M13,Backtest!A:C,3,FALSE)-1,"") -> -0.077839278 | S13: =IF(ISNUMBER(N13),P13-R13,"") -> -0.0047045685 | T13: =IF(ISNUMBER(N13),S13*$B$1,"") -> -470.45685 | U13: =IF(ISNUMBER(N13),NETWORKDAYS(M13,N13),"") -> 17
A14: 12 | B14: =IFERROR(INDEX(Backtest!$A$8:$A$5000,MATCH(A14,Backtest!$N$8:$N$5000,0)),"") -> 40669 | C14: =IFERROR(INDEX(Backtest!$A$8:$A$5000,MATCH(A14,Backtest!$O$8:$O$5000,0)),"") -> 40674 | D14: =IF(ISNUMBER(B14),Backtest!$C$1,"") -> BBDC4 | E14: =IFERROR(VLOOKUP(C14,Backtest!A:C,3,FALSE)/VLOOKUP(B14,Backtest!A:C,3,FALSE)-1,"") -> 0.015156406 | F14: =IF(ISNUMBER(C14),Backtest!$B$1,"") -> ITUB4 | G14: =IFERROR(VLOOKUP(C14,Backtest!A:C,2,FALSE)/VLOOKUP(B14,Backtest!A:C,2,FALSE)-1,"") -> 0.0062888431 | H14: =IF(ISNUMBER(C14),E14-G14,"") -> 0.0088675631 | I14: =IF(ISNUMBER(C14),H14*$B$1,"") -> 886.75631 | J14: =IF(ISNUMBER(C14),NETWORKDAYS(B14,C14),"") -> 4 | L14: 12 | M14: =IFERROR(INDEX(Backtest!$A$8:$A$5000,MATCH(L14,Backtest!$P$8:$P$5000,0)),"") -> 40612 | N14: =IFERROR(INDEX(Backtest!$A$8:$A$5000,MATCH(L14,Backtest!$Q$8:$Q$5000,0)),"") -> 40632 | O14: =IF(ISNUMBER(M14),Backtest!$B$1,"") -> ITUB4 | P14: =IFERROR(VLOOKUP(N14,Backtest!A:C,2,FALSE)/VLOOKUP(M14,Backtest!A:C,2,FALSE)-1,"") -> 0.080125532 | Q14: =IF(ISNUMBER(N14),Backtest!$C$1,"") -> BBDC4 | R14: =IFERROR(VLOOKUP(N14,Backtest!A:C,3,FALSE)/VLOOKUP(M14,Backtest!A:C,3,FALSE)-1,"") -> 0.041364101 | S14: =IF(ISNUMBER(N14),P14-R14,"") -> 0.038761432 | T14: =IF(ISNUMBER(N14),S14*$B$1,"") -> 3876.1432 | U14: =IF(ISNUMBER(N14),NETWORKDAYS(M14,N14),"") -> 15
A15: 13 | B15: =IFERROR(INDEX(Backtest!$A$8:$A$5000,MATCH(A15,Backtest!$N$8:$N$5000,0)),"") -> 40710 | C15: =IFERROR(INDEX(Backtest!$A$8:$A$5000,MATCH(A15,Backtest!$O$8:$O$5000,0)),"") -> 40711 | D15: =IF(ISNUMBER(B15),Backtest!$C$1,"") -> BBDC4 | E15: =IFERROR(VLOOKUP(C15,Backtest!A:C,3,FALSE)/VLOOKUP(B15,Backtest!A:C,3,FALSE)-1,"") -> -0.0032886272 | F15: =IF(ISNUMBER(C15),Backtest!$B$1,"") -> ITUB4 | G15: =IFERROR(VLOOKUP(C15,Backtest!A:C,2,FALSE)/VLOOKUP(B15,Backtest!A:C,2,FALSE)-1,"") -> -0.011024164 | H15: =IF(ISNUMBER(C15),E15-G15,"") -> 0.0077355366 | I15: =IF(ISNUMBER(C15),H15*$B$1,"") -> 773.55366 | J15: =IF(ISNUMBER(C15),NETWORKDAYS(B15,C15),"") -> 2 | L15: 13 | M15: =IFERROR(INDEX(Backtest!$A$8:$A$5000,MATCH(L15,Backtest!$P$8:$P$5000,0)),"") -> 40675 | N15: =IFERROR(INDEX(Backtest!$A$8:$A$5000,MATCH(L15,Backtest!$Q$8:$Q$5000,0)),"") -> 40696 | O15: =IF(ISNUMBER(M15),Backtest!$B$1,"") -> ITUB4 | P15: =IFERROR(VLOOKUP(N15,Backtest!A:C,2,FALSE)/VLOOKUP(M15,Backtest!A:C,2,FALSE)-1,"") -> -0.023299757 | Q15: =IF(ISNUMBER(N15),Backtest!$C$1,"") -> BBDC4 | R15: =IFERROR(VLOOKUP(N15,Backtest!A:C,3,FALSE)/VLOOKUP(M15,Backtest!A:C,3,FALSE)-1,"") -> -0.026171606 | S15: =IF(ISNUMBER(N15),P15-R15,"") -> 0.0028718492 | T15: =IF(ISNUMBER(N15),S15*$B$1,"") -> 287.18492 | U15: =IF(ISNUMBER(N15),NETWORKDAYS(M15,N15),"") -> 16
A16: 14 | B16: =IFERROR(INDEX(Backtest!$A$8:$A$5000,MATCH(A16,Backtest!$N$8:$N$5000,0)),"") -> 40812 | C16: =IFERROR(INDEX(Backtest!$A$8:$A$5000,MATCH(A16,Backtest!$O$8:$O$5000,0)),"") -> 40844 | D16: =IF(ISNUMBER(B16),Backtest!$C$1,"") -> BBDC4 | E16: =IFERROR(VLOOKUP(C16,Backtest!A:C,3,FALSE)/VLOOKUP(B16,Backtest!A:C,3,FALSE)-1,"") -> 0.15233095 | F16: =IF(ISNUMBER(C16),Backtest!$B$1,"") -> ITUB4 | G16: =IFERROR(VLOOKUP(C16,Backtest!A:C,2,FALSE)/VLOOKUP(B16,Backtest!A:C,2,FALSE)-1,"") -> 0.18195171 | H16: =IF(ISNUMBER(C16),E16-G16,"") -> -0.029620755 | I16: =IF(ISNUMBER(C16),H16*$B$1,"") -> -2962.0755 | J16: =IF(ISNUMBER(C16),NETWORKDAYS(B16,C16),"") -> 25 | L16: 14 | M16: =IFERROR(INDEX(Backtest!$A$8:$A$5000,MATCH(L16,Backtest!$P$8:$P$5000,0)),"") -> 40701 | N16: =IFERROR(INDEX(Backtest!$A$8:$A$5000,MATCH(L16,Backtest!$Q$8:$Q$5000,0)),"") -> 40708 | O16: =IF(ISNUMBER(M16),Backtest!$B$1,"") -> ITUB4 | P16: =IFERROR(VLOOKUP(N16,Backtest!A:C,2,FALSE)/VLOOKUP(M16,Backtest!A:C,2,FALSE)-1,"") -> -0.0081547635 | Q16: =IF(ISNUMBER(N16),Backtest!$C$1,"") -> BBDC4 | R16: =IFERROR(VLOOKUP(N16,Backtest!A:C,3,FALSE)/VLOOKUP(M16,Backtest!A:C,3,FALSE)-1,"") -> -0.013570075 | S16: =IF(ISNUMBER(N16),P16-R16,"") -> 0.0054153111 | T16: =IF(ISNUMBER(N16),S16*$B$1,"") -> 541.53111 | U16: =IF(ISNUMBER(N16),NETWORKDAYS(M16,N16),"") -> 6
A17: 15 | B17: =IFERROR(INDEX(Backtest!$A$8:$A$5000,MATCH(A17,Backtest!$N$8:$N$5000,0)),"") -> 40875 | C17: =IFERROR(INDEX(Backtest!$A$8:$A$5000,MATCH(A17,Backtest!$O$8:$O$5000,0)),"") -> 40914 | D17: =IF(ISNUMBER(B17),Backtest!$C$1,"") -> BBDC4 | E17: =IFERROR(VLOOKUP(C17,Backtest!A:C,3,FALSE)/VLOOKUP(B17,Backtest!A:C,3,FALSE)-1,"") -> 0.10912834 | F17: =IF(ISNUMBER(C17),Backtest!$B$1,"") -> ITUB4 | G17: =IFERROR(VLOOKUP(C17,Backtest!A:C,2,FALSE)/VLOOKUP(B17,Backtest!A:C,2,FALSE)-1,"") -> 0.15279636 | H17: =IF(ISNUMBER(C17),E17-G17,"") -> -0.043668014 | I17: =IF(ISNUMBER(C17),H17*$B$1,"") -> -4366.8014 | J17: =IF(ISNUMBER(C17),NETWORKDAYS(B17,C17),"") -> 30 | L17: 15 | M17: =IFERROR(INDEX(Backtest!$A$8:$A$5000,MATCH(L17,Backtest!$P$8:$P$5000,0)),"") -> 40715 | N17: =IFERROR(INDEX(Backtest!$A$8:$A$5000,MATCH(L17,Backtest!$Q$8:$Q$5000,0)),"") -> 40781 | O17: =IF(ISNUMBER(M17),Backtest!$B$1,"") -> ITUB4 | P17: =IFERROR(VLOOKUP(N17,Backtest!A:C,2,FALSE)/VLOOKUP(M17,Backtest!A:C,2,FALSE)-1,"") -> -0.21864865 | Q17: =IF(ISNUMBER(N17),Backtest!$C$1,"") -> BBDC4 | R17: =IFERROR(VLOOKUP(N17,Backtest!A:C,3,FALSE)/VLOOKUP(M17,Backtest!A:C,3,FALSE)-1,"") -> -0.12530712 | S17: =IF(ISNUMBER(N17),P17-R17,"") -> -0.093341528 | T17: =IF(ISNUMBER(N17),S17*$B$1,"") -> -9334.1528 | U17: =IF(ISNUMBER(N17),NETWORKDAYS(M17,N17),"") -> 49
A18: 16 | B18: =IFERROR(INDEX(Backtest!$A$8:$A$5000,MATCH(A18,Backtest!$N$8:$N$5000,0)),"") -> 40918 | C18: =IFERROR(INDEX(Backtest!$A$8:$A$5000,MATCH(A18,Backtest!$O$8:$O$5000,0)),"") -> 40932 | D18: =IF(ISNUMBER(B18),Backtest!$C$1,"") -> BBDC4 | E18: =IFERROR(VLOOKUP(C18,Backtest!A:C,3,FALSE)/VLOOKUP(B18,Backtest!A:C,3,FALSE)-1,"") -> 0.020788394 | F18: =IF(ISNUMBER(C18),Backtest!$B$1,"") -> ITUB4 | G18: =IFERROR(VLOOKUP(C18,Backtest!A:C,2,FALSE)/VLOOKUP(B18,Backtest!A:C,2,FALSE)-1,"") -> 0.0039300546 | H18: =IF(ISNUMBER(C18),E18-G18,"") -> 0.01685834 | I18: =IF(ISNUMBER(C18),H18*$B$1,"") -> 1685.834 | J18: =IF(ISNUMBER(C18),NETWORKDAYS(B18,C18),"") -> 11 | L18: 16 | M18: =IFERROR(INDEX(Backtest!$A$8:$A$5000,MATCH(L18,Backtest!$P$8:$P$5000,0)),"") -> 40799 | N18: =IFERROR(INDEX(Backtest!$A$8:$A$5000,MATCH(L18,Backtest!$Q$8:$Q$5000,0)),"") -> 40809 | O18: =IF(ISNUMBER(M18),Backtest!$B$1,"") -> ITUB4 | P18: =IFERROR(VLOOKUP(N18,Backtest!A:C,2,FALSE)/VLOOKUP(M18,Backtest!A:C,2,FALSE)-1,"") -> -0.021060383 | Q18: =IF(ISNUMBER(N18),Backtest!$C$1,"") -> BBDC4 | R18: =IFERROR(VLOOKUP(N18,Backtest!A:C,3,FALSE)/VLOOKUP(M18,Backtest!A:C,3,FALSE)-1,"") -> -0.044484192 | S18: =IF(ISNUMBER(N18),P18-R18,"") -> 0.023423808 | T18: =IF(ISNUMBER(N18),S18*$B$1,"") -> 2342.3808 | U18: =IF(ISNUMBER(N18),NETWORKDAYS(M18,N18),"") -> 9
A19: 17 | B19: =IFERROR(INDEX(Backtest!$A$8:$A$5000,MATCH(A19,Backtest!$N$8:$N$5000,0)),"") -> 40940 | C19: =IFERROR(INDEX(Backtest!$A$8:$A$5000,MATCH(A19,Backtest!$O$8:$O$5000,0)),"") -> 40974 | D19: =IF(ISNUMBER(B19),Backtest!$C$1,"") -> BBDC4 | E19: =IFERROR(VLOOKUP(C19,Backtest!A:C,3,FALSE)/VLOOKUP(B19,Backtest!A:C,3,FALSE)-1,"") -> -0.011512964 | F19: =IF(ISNUMBER(C19),Backtest!$B$1,"") -> ITUB4 | G19: =IFERROR(VLOOKUP(C19,Backtest!A:C,2,FALSE)/VLOOKUP(B19,Backtest!A:C,2,FALSE)-1,"") -> 0.006505237 | H19: =IF(ISNUMBER(C19),E19-G19,"") -> -0.018018201 | I19: =IF(ISNUMBER(C19),H19*$B$1,"") -> -1801.8201 | J19: =IF(ISNUMBER(C19),NETWORKDAYS(B19,C19),"") -> 25 | L19: 17 | M19: =IFERROR(INDEX(Backtest!$A$8:$A$5000,MATCH(L19,Backtest!$P$8:$P$5000,0)),"") -> 40844 | N19: =IFERROR(INDEX(Backtest!$A$8:$A$5000,MATCH(L19,Backtest!$Q$8:$Q$5000,0)),"") -> 40870 | O19: =IF(ISNUMBER(M19),Backtest!$B$1,"") -> ITUB4 | P19: =IFERROR(VLOOKUP(N19,Backtest!A:C,2,FALSE)/VLOOKUP(M19,Backtest!A:C,2,FALSE)-1,"") -> -0.10622888 | Q19: =IF(ISNUMBER(N19),Backtest!$C$1,"") -> BBDC4 | R19: =IFERROR(VLOOKUP(N19,Backtest!A:C,3,FALSE)/VLOOKUP(M19,Backtest!A:C,3,FALSE)-1,"") -> -0.10766854 | S19: =IF(ISNUMBER(N19),P19-R19,"") -> 0.0014396644 | T19: =IF(ISNUMBER(N19),S19*$B$1,"") -> 143.96644 | U19: =IF(ISNUMBER(N19),NETWORKDAYS(M19,N19),"") -> 19
A20: 18 | B20: =IFERROR(INDEX(Backtest!$A$8:$A$5000,MATCH(A20,Backtest!$N$8:$N$5000,0)),"") -> 41057 | C20: =IFERROR(INDEX(Backtest!$A$8:$A$5000,MATCH(A20,Backtest!$O$8:$O$5000,0)),"") -> 41058 | D20: =IF(ISNUMBER(B20),Backtest!$C$1,"") -> BBDC4 | E20: =IFERROR(VLOOKUP(C20,Backtest!A:C,3,FALSE)/VLOOKUP(B20,Backtest!A:C,3,FALSE)-1,"") -> 0.01054824 | F20: =IF(ISNUMBER(C20),Backtest!$B$1,"") -> ITUB4 | G20: =IFERROR(VLOOKUP(C20,Backtest!A:C,2,FALSE)/VLOOKUP(B20,Backtest!A:C,2,FALSE)-1,"") -> -0.0094645976 | H20: =IF(ISNUMBER(C20),E20-G20,"") -> 0.020012838 | I20: =IF(ISNUMBER(C20),H20*$B$1,"") -> 2001.2838 | J20: =IF(ISNUMBER(C20),NETWORKDAYS(B20,C20),"") -> 2 | L20: 18 | M20: =IFERROR(INDEX(Backtest!$A$8:$A$5000,MATCH(L20,Backtest!$P$8:$P$5000,0)),"") -> 40932 | N20: =IFERROR(INDEX(Backtest!$A$8:$A$5000,MATCH(L20,Backtest!$Q$8:$Q$5000,0)),"") -> 40940 | O20: =IF(ISNUMBER(M20),Backtest!$B$1,"") -> ITUB4 | P20: =IFERROR(VLOOKUP(N20,Backtest!A:C,2,FALSE)/VLOOKUP(M20,Backtest!A:C,2,FALSE)-1,"") -> -0.00036798549 | Q20: =IF(ISNUMBER(N20),Backtest!$C$1,"") -> BBDC4 | R20: =IFERROR(VLOOKUP(N20,Backtest!A:C,3,FALSE)/VLOOKUP(M20,Backtest!A:C,3,FALSE)-1,"") -> -0.033324435 | S20: =IF(ISNUMBER(N20),P20-R20,"") -> 0.03295645 | T20: =IF(ISNUMBER(N20),S20*$B$1,"") -> 3295.645 | U20: =IF(ISNUMBER(N20),NETWORKDAYS(M20,N20),"") -> 7
A21: 19 | B21: =IFERROR(INDEX(Backtest!$A$8:$A$5000,MATCH(A21,Backtest!$N$8:$N$5000,0)),"") -> 41103 | C21: =IFERROR(INDEX(Backtest!$A$8:$A$5000,MATCH(A21,Backtest!$O$8:$O$5000,0)),"") -> 41128 | D21: =IF(ISNUMBER(B21),Backtest!$C$1,"") -> BBDC4 | E21: =IFERROR(VLOOKUP(C21,Backtest!A:C,3,FALSE)/VLOOKUP(B21,Backtest!A:C,3,FALSE)-1,"") -> 0.11943934 | F21: =IF(ISNUMBER(C21),Backtest!$B$1,"") -> ITUB4 | G21: =IFERROR(VLOOKUP(C21,Backtest!A:C,2,FALSE)/VLOOKUP(B21,Backtest!A:C,2,FALSE)-1,"") -> 0.13597337 | H21: =IF(ISNUMBER(C21),E21-G21,"") -> -0.016534034 | I21: =IF(ISNUMBER(C21),H21*$B$1,"") -> -1653.4034 | J21: =IF(ISNUMBER(C21),NETWORKDAYS(B21,C21),"") -> 18 | L21: 19 | M21: =IFERROR(INDEX(Backtest!$A$8:$A$5000,MATCH(L21,Backtest!$P$8:$P$5000,0)),"") -> 40981 | N21: =IFERROR(INDEX(Backtest!$A$8:$A$5000,MATCH(L21,Backtest!$Q$8:$Q$5000,0)),"") -> 41045 | O21: =IF(ISNUMBER(M21),Backtest!$B$1,"") -> ITUB4 | P21: =IFERROR(VLOOKUP(N21,Backtest!A:C,2,FALSE)/VLOOKUP(M21,Backtest!A:C,2,FALSE)-1,"") -> -0.25389775 | Q21: =IF(ISNUMBER(N21),Backtest!$C$1,"") -> BBDC4 | R21: =IFERROR(VLOOKUP(N21,Backtest!A:C,3,FALSE)/VLOOKUP(M21,Backtest!A:C,3,FALSE)-1,"") -> -0.14335859 | S21: =IF(ISNUMBER(N21),P21-R21,"") -> -0.11053917 | T21: =IF(ISNUMBER(N21),S21*$B$1,"") -> -11053.917 | U21: =IF(ISNUMBER(N21),NETWORKDAYS(M21,N21),"") -> 47
A22: 20 | B22: =IFERROR(INDEX(Backtest!$A$8:$A$5000,MATCH(A22,Backtest!$N$8:$N$5000,0)),"") -> 41249 | C22: =IFERROR(INDEX(Backtest!$A$8:$A$5000,MATCH(A22,Backtest!$O$8:$O$5000,0)),"") -> 41253 | D22: =IF(ISNUMBER(B22),Backtest!$C$1,"") -> BBDC4 | E22: =IFERROR(VLOOKUP(C22,Backtest!A:C,3,FALSE)/VLOOKUP(B22,Backtest!A:C,3,FALSE)-1,"") -> 0.013666114 | F22: =IF(ISNUMBER(C22),Backtest!$B$1,"") -> ITUB4 | G22: =IFERROR(VLOOKUP(C22,Backtest!A:C,2,FALSE)/VLOOKUP(B22,Backtest!A:C,2,FALSE)-1,"") -> 0.0024441333 | H22: =IF(ISNUMBER(C22),E22-G22,"") -> 0.01122198 | I22: =IF(ISNUMBER(C22),H22*$B$1,"") -> 1122.198 | J22: =IF(ISNUMBER(C22),NETWORKDAYS(B22,C22),"") -> 3 | L22: 20 | M22: =IFERROR(INDEX(Backtest!$A$8:$A$5000,MATCH(L22,Backtest!$P$8:$P$5000,0)),"") -> 41050 | N22: =IFERROR(INDEX(Backtest!$A$8:$A$5000,MATCH(L22,Backtest!$Q$8:$Q$5000,0)),"") -> 41052 | O22: =IF(ISNUMBER(M22),Backtest!$B$1,"") -> ITUB4 | P22: =IFERROR(VLOOKUP(N22,Backtest!A:C,2,FALSE)/VLOOKUP(M22,Backtest!A:C,2,FALSE)-1,"") -> 0.04891482 | Q22: =IF(ISNUMBER(N22),Backtest!$C$1,"") -> BBDC4 | R22: =IFERROR(VLOOKUP(N22,Backtest!A:C,3,FALSE)/VLOOKUP(M22,Backtest!A:C,3,FALSE)-1,"") -> -0.011739643 | S22: =IF(ISNUMBER(N22),P22-R22,"") -> 0.060654463 | T22: =IF(ISNUMBER(N22),S22*$B$1,"") -> 6065.4463 | U22: =IF(ISNUMBER(N22),NETWORKDAYS(M22,N22),"") -> 3
... A72: 70 | B72: =IFERROR(INDEX(Backtest!$A$8:$A$5000,MATCH(A72,Backtest!$N$8:$N$5000,0)),"") -> 43292 | C72: =IFERROR(INDEX(Backtest!$A$8:$A$5000,MATCH(A72,Backtest!$O$8:$O$5000,0)),"") -> 43297 | D72: =IF(ISNUMBER(B72),Backtest!$C$1,"") -> BBDC4 | E72: =IFERROR(VLOOKUP(C72,Backtest!A:C,3,FALSE)/VLOOKUP(B72,Backtest!A:C,3,FALSE)-1,"") -> 0.054530752 | F72: =IF(ISNUMBER(C72),Backtest!$B$1,"") -> ITUB4 | G72: =IFERROR(VLOOKUP(C72,Backtest!A:C,2,FALSE)/VLOOKUP(B72,Backtest!A:C,2,FALSE)-1,"") -> 0.041076739 | H72: =IF(ISNUMBER(C72),E72-G72,"") -> 0.013454013 | I72: =IF(ISNUMBER(C72),H72*$B$1,"") -> 1345.4013 | J72: =IF(ISNUMBER(C72),NETWORKDAYS(B72,C72),"") -> 4 | L72: 70 | M72: =IFERROR(INDEX(Backtest!$A$8:$A$5000,MATCH(L72,Backtest!$P$8:$P$5000,0)),"") -> 42958 | N72: =IFERROR(INDEX(Backtest!$A$8:$A$5000,MATCH(L72,Backtest!$Q$8:$Q$5000,0)),"") -> 42984 | O72: =IF(ISNUMBER(M72),Backtest!$B$1,"") -> ITUB4 | P72: =IFERROR(VLOOKUP(N72,Backtest!A:C,2,FALSE)/VLOOKUP(M72,Backtest!A:C,2,FALSE)-1,"") -> 0.083573568 | Q72: =IF(ISNUMBER(N72),Backtest!$C$1,"") -> BBDC4 | R72: =IFERROR(VLOOKUP(N72,Backtest!A:C,3,FALSE)/VLOOKUP(M72,Backtest!A:C,3,FALSE)-1,"") -> 0.082641888 | S72: =IF(ISNUMBER(N72),P72-R72,"") -> 0.00093167946 | T72: =IF(ISNUMBER(N72),S72*$B$1,"") -> 93.167946 | U72: =IF(ISNUMBER(N72),NETWORKDAYS(M72,N72),"") -> 19
A73: 71 | B73: =IFERROR(INDEX(Backtest!$A$8:$A$5000,MATCH(A73,Backtest!$N$8:$N$5000,0)),"") -> 43333 | C73: =IFERROR(INDEX(Backtest!$A$8:$A$5000,MATCH(A73,Backtest!$O$8:$O$5000,0)),"") -> 43377 | D73: =IF(ISNUMBER(B73),Backtest!$C$1,"") -> BBDC4 | E73: =IFERROR(VLOOKUP(C73,Backtest!A:C,3,FALSE)/VLOOKUP(B73,Backtest!A:C,3,FALSE)-1,"") -> 0.12058247 | F73: =IF(ISNUMBER(C73),Backtest!$B$1,"") -> ITUB4 | G73: =IFERROR(VLOOKUP(C73,Backtest!A:C,2,FALSE)/VLOOKUP(B73,Backtest!A:C,2,FALSE)-1,"") -> 0.12989273 | H73: =IF(ISNUMBER(E73),E73-G73,"") -> -0.0093102586 | I73: =IF(ISNUMBER(G73),H73*$B$1,"") -> -931.02586 | J73: =IF(ISNUMBER(C73),NETWORKDAYS(B73,C73),"") -> 33 | L73: 71 | M73: =IFERROR(INDEX(Backtest!$A$8:$A$5000,MATCH(L73,Backtest!$P$8:$P$5000,0)),"") -> 42998 | N73: =IFERROR(INDEX(Backtest!$A$8:$A$5000,MATCH(L73,Backtest!$Q$8:$Q$5000,0)),"") -> 43003 | O73: =IF(ISNUMBER(M73),Backtest!$B$1,"") -> ITUB4 | P73: =IFERROR(VLOOKUP(N73,Backtest!A:C,2,FALSE)/VLOOKUP(M73,Backtest!A:C,2,FALSE)-1,"") -> -0.0050799317 | Q73: =IF(ISNUMBER(N73),Backtest!$C$1,"") -> BBDC4 | R73: =IFERROR(VLOOKUP(N73,Backtest!A:C,3,FALSE)/VLOOKUP(M73,Backtest!A:C,3,FALSE)-1,"") -> -0.019112493 | S73: =IF(ISNUMBER(P73),P73-R73,"") -> 0.014032561 | T73: =IF(ISNUMBER(R73),S73*$B$1,"") -> 1403.2561 | U73: =IF(ISNUMBER(N73),NETWORKDAYS(M73,N73),"") -> 4
A74: 72 | B74: =IFERROR(INDEX(Backtest!$A$8:$A$5000,MATCH(A74,Backtest!$N$8:$N$5000,0)),"") -> 43378 | C74: =IFERROR(INDEX(Backtest!$A$8:$A$5000,MATCH(A74,Backtest!$O$8:$O$5000,0)),"") -> 43382 | D74: =IF(ISNUMBER(B74),Backtest!$C$1,"") -> BBDC4 | E74: =IFERROR(VLOOKUP(C74,Backtest!A:C,3,FALSE)/VLOOKUP(B74,Backtest!A:C,3,FALSE)-1,"") -> 0.071658825 | F74: =IF(ISNUMBER(C74),Backtest!$B$1,"") -> ITUB4 | G74: =IFERROR(VLOOKUP(C74,Backtest!A:C,2,FALSE)/VLOOKUP(B74,Backtest!A:C,2,FALSE)-1,"") -> 0.053979745 | H74: =IF(ISNUMBER(E74),E74-G74,"") -> 0.01767908 | I74: =IF(ISNUMBER(G74),H74*$B$1,"") -> 1767.908 | J74: =IF(ISNUMBER(C74),NETWORKDAYS(B74,C74),"") -> 3 | L74: 72 | M74: =IFERROR(INDEX(Backtest!$A$8:$A$5000,MATCH(L74,Backtest!$P$8:$P$5000,0)),"") -> 43039 | N74: =IFERROR(INDEX(Backtest!$A$8:$A$5000,MATCH(L74,Backtest!$Q$8:$Q$5000,0)),"") -> 43040 | O74: =IF(ISNUMBER(M74),Backtest!$B$1,"") -> ITUB4 | P74: =IFERROR(VLOOKUP(N74,Backtest!A:C,2,FALSE)/VLOOKUP(M74,Backtest!A:C,2,FALSE)-1,"") -> -0.016771794 | Q74: =IF(ISNUMBER(N74),Backtest!$C$1,"") -> BBDC4 | R74: =IFERROR(VLOOKUP(N74,Backtest!A:C,3,FALSE)/VLOOKUP(M74,Backtest!A:C,3,FALSE)-1,"") -> -0.031142276 | S74: =IF(ISNUMBER(P74),P74-R74,"") -> 0.014370482 | T74: =IF(ISNUMBER(R74),S74*$B$1,"") -> 1437.0482 | U74: =IF(ISNUMBER(N74),NETWORKDAYS(M74,N74),"") -> 2
A75: 73 | B75: =IFERROR(INDEX(Backtest!$A$8:$A$5000,MATCH(A75,Backtest!$N$8:$N$5000,0)),"") -> 43531 | C75: =IFERROR(INDEX(Backtest!$A$8:$A$5000,MATCH(A75,Backtest!$O$8:$O$5000,0)),"") -> 43538 | D75: =IF(ISNUMBER(B75),Backtest!$C$1,"") -> BBDC4 | E75: =IFERROR(VLOOKUP(C75,Backtest!A:C,3,FALSE)/VLOOKUP(B75,Backtest!A:C,3,FALSE)-1,"") -> 0.070571475 | F75: =IF(ISNUMBER(C75),Backtest!$B$1,"") -> ITUB4 | G75: =IFERROR(VLOOKUP(C75,Backtest!A:C,2,FALSE)/VLOOKUP(B75,Backtest!A:C,2,FALSE)-1,"") -> 0.041890556 | H75: =IF(ISNUMBER(E75),E75-G75,"") -> 0.028680919 | I75: =IF(ISNUMBER(G75),H75*$B$1,"") -> 2868.0919 | J75: =IF(ISNUMBER(C75),NETWORKDAYS(B75,C75),"") -> 6 | L75: 73 | M75: =IFERROR(INDEX(Backtest!$A$8:$A$5000,MATCH(L75,Backtest!$P$8:$P$5000,0)),"") -> 43082 | N75: =IFERROR(INDEX(Backtest!$A$8:$A$5000,MATCH(L75,Backtest!$Q$8:$Q$5000,0)),"") -> 43122 | O75: =IF(ISNUMBER(M75),Backtest!$B$1,"") -> ITUB4 | P75: =IFERROR(VLOOKUP(N75,Backtest!A:C,2,FALSE)/VLOOKUP(M75,Backtest!A:C,2,FALSE)-1,"") -> 0.15969558 | Q75: =IF(ISNUMBER(N75),Backtest!$C$1,"") -> BBDC4 | R75: =IFERROR(VLOOKUP(N75,Backtest!A:C,3,FALSE)/VLOOKUP(M75,Backtest!A:C,3,FALSE)-1,"") -> 0.20380679 | S75: =IF(ISNUMBER(P75),P75-R75,"") -> -0.044111204 | T75: =IF(ISNUMBER(R75),S75*$B$1,"") -> -4411.1204 | U75: =IF(ISNUMBER(N75),NETWORKDAYS(M75,N75),"") -> 29
A76: 74 | B76: =IFERROR(INDEX(Backtest!$A$8:$A$5000,MATCH(A76,Backtest!$N$8:$N$5000,0)),"") -> 43587 | C76: =IFERROR(INDEX(Backtest!$A$8:$A$5000,MATCH(A76,Backtest!$O$8:$O$5000,0)),"") -> 43588 | D76: =IF(ISNUMBER(B76),Backtest!$C$1,"") -> BBDC4 | E76: =IFERROR(VLOOKUP(C76,Backtest!A:C,3,FALSE)/VLOOKUP(B76,Backtest!A:C,3,FALSE)-1,"") -> 0.010601952 | F76: =IF(ISNUMBER(C76),Backtest!$B$1,"") -> ITUB4 | G76: =IFERROR(VLOOKUP(C76,Backtest!A:C,2,FALSE)/VLOOKUP(B76,Backtest!A:C,2,FALSE)-1,"") -> -0.0096947757 | H76: =IF(ISNUMBER(E76),E76-G76,"") -> 0.020296728 | I76: =IF(ISNUMBER(G76),H76*$B$1,"") -> 2029.6728 | J76: =IF(ISNUMBER(C76),NETWORKDAYS(B76,C76),"") -> 2 | L76: 74 | M76: =IFERROR(INDEX(Backtest!$A$8:$A$5000,MATCH(L76,Backtest!$P$8:$P$5000,0)),"") -> 43124 | N76: =IFERROR(INDEX(Backtest!$A$8:$A$5000,MATCH(L76,Backtest!$Q$8:$Q$5000,0)),"") -> 43126 | O76: =IF(ISNUMBER(M76),Backtest!$B$1,"") -> ITUB4 | P76: =IFERROR(VLOOKUP(N76,Backtest!A:C,2,FALSE)/VLOOKUP(M76,Backtest!A:C,2,FALSE)-1,"") -> 0.050229087 | Q76: =IF(ISNUMBER(N76),Backtest!$C$1,"") -> BBDC4 | R76: =IFERROR(VLOOKUP(N76,Backtest!A:C,3,FALSE)/VLOOKUP(M76,Backtest!A:C,3,FALSE)-1,"") -> 0.035175579 | S76: =IF(ISNUMBER(P76),P76-R76,"") -> 0.015053508 | T76: =IF(ISNUMBER(R76),S76*$B$1,"") -> 1505.3508 | U76: =IF(ISNUMBER(N76),NETWORKDAYS(M76,N76),"") -> 3
A77: 75 | B77: =IFERROR(INDEX(Backtest!$A$8:$A$5000,MATCH(A77,Backtest!$N$8:$N$5000,0)),"") -> 43592 | C77: =IFERROR(INDEX(Backtest!$A$8:$A$5000,MATCH(A77,Backtest!$O$8:$O$5000,0)),"") -> 43593 | D77: =IF(ISNUMBER(B77),Backtest!$C$1,"") -> BBDC4 | E77: =IFERROR(VLOOKUP(C77,Backtest!A:C,3,FALSE)/VLOOKUP(B77,Backtest!A:C,3,FALSE)-1,"") -> 0.12277828 | F77: =IF(ISNUMBER(C77),Backtest!$B$1,"") -> ITUB4 | G77: =IFERROR(VLOOKUP(C77,Backtest!A:C,2,FALSE)/VLOOKUP(B77,Backtest!A:C,2,FALSE)-1,"") -> 0.011349884 | H77: =IF(ISNUMBER(E77),E77-G77,"") -> 0.1114284 | I77: =IF(ISNUMBER(G77),H77*$B$1,"") -> 11142.84 | J77: =IF(ISNUMBER(C77),NETWORKDAYS(B77,C77),"") -> 2 | L77: 75 | M77: =IFERROR(INDEX(Backtest!$A$8:$A$5000,MATCH(L77,Backtest!$P$8:$P$5000,0)),"") -> 43181 | N77: =IFERROR(INDEX(Backtest!$A$8:$A$5000,MATCH(L77,Backtest!$Q$8:$Q$5000,0)),"") -> 43199 | O77: =IF(ISNUMBER(M77),Backtest!$B$1,"") -> ITUB4 | P77: =IFERROR(VLOOKUP(N77,Backtest!A:C,2,FALSE)/VLOOKUP(M77,Backtest!A:C,2,FALSE)-1,"") -> 0.0041010651 | Q77: =IF(ISNUMBER(N77),Backtest!$C$1,"") -> BBDC4 | R77: =IFERROR(VLOOKUP(N77,Backtest!A:C,3,FALSE)/VLOOKUP(M77,Backtest!A:C,3,FALSE)-1,"") -> -0.01234129 | S77: =IF(ISNUMBER(P77),P77-R77,"") -> 0.016442355 | T77: =IF(ISNUMBER(R77),S77*$B$1,"") -> 1644.2355 | U77: =IF(ISNUMBER(N77),NETWORKDAYS(M77,N77),"") -> 13
A78: 76 | B78: =IFERROR(INDEX(Backtest!$A$8:$A$5000,MATCH(A78,Backtest!$N$8:$N$5000,0)),"") -> 43634 | C78: =IFERROR(INDEX(Backtest!$A$8:$A$5000,MATCH(A78,Backtest!$O$8:$O$5000,0)),"") -> 43641 | D78: =IF(ISNUMBER(B78),Backtest!$C$1,"") -> BBDC4 | E78: =IFERROR(VLOOKUP(C78,Backtest!A:C,3,FALSE)/VLOOKUP(B78,Backtest!A:C,3,FALSE)-1,"") -> 0.034663224 | F78: =IF(ISNUMBER(C78),Backtest!$B$1,"") -> ITUB4 | G78: =IFERROR(VLOOKUP(C78,Backtest!A:C,2,FALSE)/VLOOKUP(B78,Backtest!A:C,2,FALSE)-1,"") -> 0.023542689 | H78: =IF(ISNUMBER(E78),E78-G78,"") -> 0.011120535 | I78: =IF(ISNUMBER(G78),H78*$B$1,"") -> 1112.0535 | J78: =IF(ISNUMBER(C78),NETWORKDAYS(B78,C78),"") -> 6 | L78: 76 | M78: =IFERROR(INDEX(Backtest!$A$8:$A$5000,MATCH(L78,Backtest!$P$8:$P$5000,0)),"") -> 43224 | N78: =IFERROR(INDEX(Backtest!$A$8:$A$5000,MATCH(L78,Backtest!$Q$8:$Q$5000,0)),"") -> 43236 | O78: =IF(ISNUMBER(M78),Backtest!$B$1,"") -> ITUB4 | P78: =IFERROR(VLOOKUP(N78,Backtest!A:C,2,FALSE)/VLOOKUP(M78,Backtest!A:C,2,FALSE)-1,"") -> 0.017168115 | Q78: =IF(ISNUMBER(N78),Backtest!$C$1,"") -> BBDC4 | R78: =IFERROR(VLOOKUP(N78,Backtest!A:C,3,FALSE)/VLOOKUP(M78,Backtest!A:C,3,FALSE)-1,"") -> -0.0087893615 | S78: =IF(ISNUMBER(P78),P78-R78,"") -> 0.025957477 | T78: =IF(ISNUMBER(R78),S78*$B$1,"") -> 2595.7477 | U78: =IF(ISNUMBER(N78),NETWORKDAYS(M78,N78),"") -> 9
A79: 77 | B79: =IFERROR(INDEX(Backtest!$A$8:$A$5000,MATCH(A79,Backtest!$N$8:$N$5000,0)),"") -> 43642 | C79: =IFERROR(INDEX(Backtest!$A$8:$A$5000,MATCH(A79,Backtest!$O$8:$O$5000,0)),"") -> 43649 | D79: =IF(ISNUMBER(B79),Backtest!$C$1,"") -> BBDC4 | E79: =IFERROR(VLOOKUP(C79,Backtest!A:C,3,FALSE)/VLOOKUP(B79,Backtest!A:C,3,FALSE)-1,"") -> 0.013499345 | F79: =IF(ISNUMBER(C79),Backtest!$B$1,"") -> ITUB4 | G79: =IFERROR(VLOOKUP(C79,Backtest!A:C,2,FALSE)/VLOOKUP(B79,Backtest!A:C,2,FALSE)-1,"") -> 0.002332454 | H79: =IF(ISNUMBER(E79),E79-G79,"") -> 0.011166891 | I79: =IF(ISNUMBER(G79),H79*$B$1,"") -> 1116.6891 | J79: =IF(ISNUMBER(C79),NETWORKDAYS(B79,C79),"") -> 6 | L79: 77 | M79: =IFERROR(INDEX(Backtest!$A$8:$A$5000,MATCH(L79,Backtest!$P$8:$P$5000,0)),"") -> 43238 | N79: =IFERROR(INDEX(Backtest!$A$8:$A$5000,MATCH(L79,Backtest!$Q$8:$Q$5000,0)),"") -> 43244 | O79: =IF(ISNUMBER(M79),Backtest!$B$1,"") -> ITUB4 | P79: =IFERROR(VLOOKUP(N79,Backtest!A:C,2,FALSE)/VLOOKUP(M79,Backtest!A:C,2,FALSE)-1,"") -> 0.0042050675 | Q79: =IF(ISNUMBER(N79),Backtest!$C$1,"") -> BBDC4 | R79: =IFERROR(VLOOKUP(N79,Backtest!A:C,3,FALSE)/VLOOKUP(M79,Backtest!A:C,3,FALSE)-1,"") -> -0.011115733 | S79: =IF(ISNUMBER(P79),P79-R79,"") -> 0.0153208 | T79: =IF(ISNUMBER(R79),S79*$B$1,"") -> 1532.08 | U79: =IF(ISNUMBER(N79),NETWORKDAYS(M79,N79),"") -> 5
